Workbook

Sheet 筆記
A1: 高科大 | B1: 不影響現流部分，其中有一項是不動產、廠房及設備與應付未付數同額增加明細(+)133,340千元，分別帳列應付款、其他長期負債(其他長期應付款)406
A3: 本年度預計舉借數合計359,601千元，與現金流量綜計表長期負債增加數509,601千元，差異數150,000 千元，係因現金流量綜計表所列長期負債增加數，尚包括國立大學校院校務基金(綜計)以前年度長期借款 保留數150,000千元；本年度預計償還數合計200,284千元，與現金流量綜計表長期負債減少數200,735 千元，差異數451千元，係因現金流量綜計表所列長期負債減少數，除長期借款外，尚包括本年度減少 國立大學校院校務基金(綜計)應付租賃款451千元。

Sheet 大學-自己調整
A1: 國立大學校院校務基金(彙計表) | K1: =L1+2 | L1: 0
A2: 預計平衡表與現金流量表勾稽底稿
A3: 中華民國116年度
G4: G欄=B欄期初數+C至F欄調整項目 | J4: J欄=教育部「現流表」原始資料 | L4: L欄=教育部「平衡表」期末數
A5: 科目 | B5: 115.12.31 | C5: 調整項目 | G5: 116.12.31 | H5: 現金流量表勾稽項目
B6: 預計數 | D6: 借方 | F6: 貸方 | G6: 預計數 | L6: 教育部 平衡表 | M6: M欄=自行調整後平衡表期末數與教育部之平衡表期末數之差異數
A7: 資產 | H7: ▼業務活動之現金流量 | K7: 自己拉現流表公式 | M7: 差異數要再加(減) | O7: O欄=教育部「平衡表」之比較增減 | Q7: Q欄=自行調整調整項目借貸方合計淨值，用來跟教育部之比較增減勾稽
A8: 流動資產 | B8: =SUM(臺大:東專!B7) | D8: =SUM(臺大:東專!D7) | F8: =SUM(臺大:東專!F7) | G8: =SUM(臺大:東專!G7) | H8: 本期賸餘（短絀） | I8: A | J8: =SUM(臺大:東專!J7) | K8: =-SUMIF($C$7:$C$127,I8,$D$7:$D$127)+SUMIF($E$7:$E$127,I8,$F$7:$F$127) | L8: =VLOOKUP(A8,$A$139:$AW$244,$K$1,FALSE) | M8: =L8-G8 | O8: =L8-B8 | Q8: =D8-F8 | S8: =K8-J8
A9: 現金 | B9: =SUM(臺大:東專!B8) | C9: B | D9: =SUM(臺大:東專!D8) | E9: B | F9: =SUM(臺大:東專!F8) | G9: =SUM(臺大:東專!G8) | H9: 利息股利之調整 | J9: =SUM(臺大:東專!J8) | K9: =SUM(K10:K12) | L9: =VLOOKUP(A9,$A$139:$AW$244,$K$1,FALSE) | M9: =L9-G9 | O9: =L9-B9 | Q9: =D9-F9 | S9: =J9-K9
A10: 流動金融資產 | B10: =SUM(臺大:東專!B9) | C10: 231 | D10: =SUM(臺大:東專!D9) | E10: 211 | F10: =SUM(臺大:東專!F9) | G10: =SUM(臺大:東專!G9) | H10: 利息收入 | J10: =SUM(臺大:東專!J9) | K10: =J10 | L10: =VLOOKUP(A10,$A$139:$AW$244,$K$1,FALSE) | M10: =L10-G10 | O10: =L10-B10 | Q10: =D10-F10 | S10: =J10-K10
B11: =SUM(臺大:東專!B10) | C11: 125 | D11: =SUM(臺大:東專!D10) | F11: =SUM(臺大:東專!F10) | G11: =SUM(臺大:東專!G10) | H11: 股利收入 | J11: =SUM(臺大:東專!J10) | K11: =J11 | O11: =L11-B12 | Q11: =D12-F12 | S11: =J11-K11
A12: 應收款項 | B12: =SUM(臺大:東專!B11) | C12: 151 | D12: =SUM(臺大:東專!D11) | E12: 151 | F12: =SUM(臺大:東專!F11) | G12: =SUM(臺大:東專!G11) | H12: 利息費用 | J12: =SUM(臺大:東專!J11) | K12: =J12 | L12: =VLOOKUP(A12,$A$139:$AW$244,$K$1,FALSE) | M12: =L12-G12 | O12: =L12-B13 | Q12: =D13-F13 | S12: =J12-K12
B13: =SUM(臺大:東專!B12) | D13: =SUM(臺大:東專!D12) | F13: =SUM(臺大:東專!F12) | G13: =SUM(臺大:東專!G12) | H13: 未計利息股利之本期賸餘（短絀） | J13: =SUM(臺大:東專!J12) | K13: =K8+K9 | O13: =L13-B14 | Q13: =D14-F14 | S13: =J13-K13
A14: 存貨 | B14: =SUM(臺大:東專!B13) | C14: 151 | D14: =SUM(臺大:東專!D13) | E14: 151 | F14: =SUM(臺大:東專!F13) | G14: =SUM(臺大:東專!G13) | H14: 調整項目 | J14: =SUM(臺大:東專!J13) | K14: =SUM(K15,K25,K28,K35,K34) | L14: =VLOOKUP(A14,$A$139:$AW$244,$K$1,FALSE) | M14: =L14-G14 | O14: =L14-B15 | Q14: =D15-F15 | S14: =J14-K14
A15: 生產性生物資產－流動 | B15: =SUM(臺大:東專!B14) | C15: 151 | D15: =SUM(臺大:東專!D14) | E15: 151 | F15: =SUM(臺大:東專!F14) | G15: =SUM(臺大:東專!G14) | H15: 折舊、減損及折耗 | J15: =SUM(臺大:東專!J14) | K15: =SUM(K16:K24) | L15: =VLOOKUP(A15,$A$139:$AW$244,$K$1,FALSE) | M15: =L15-G15 | O15: =L15-B16 | Q15: =D16-F16 | S15: =J15-K15
A16: 預付款項 | B16: =SUM(臺大:東專!B15) | C16: 151 | D16: =SUM(臺大:東專!D15) | E16: 151 | F16: =SUM(臺大:東專!F15) | G16: =SUM(臺大:東專!G15) | H16: 土地改良物 | I16: 101 | J16: =SUM(臺大:東專!J15) | K16: =-SUMIF($C$7:$C$127,I16,$D$7:$D$127)+SUMIF($E$7:$E$127,I16,$F$7:$F$127) | L16: =VLOOKUP(A16,$A$139:$AW$244,$K$1,FALSE) | M16: =L16-G16 | O16: =L16-B17 | Q16: =D17-F17 | S16: =J16-K16
A17: 短期貸墊款 | B17: =SUM(臺大:東專!B16) | C17: 151 | D17: =SUM(臺大:東專!D16) | E17: 212 | F17: =SUM(臺大:東專!F16) | G17: =SUM(臺大:東專!G16) | H17: 房屋及建築 | I17: 102 | J17: =SUM(臺大:東專!J16) | K17: =-SUMIF($C$7:$C$127,I17,$D$7:$D$127)+SUMIF($E$7:$E$127,I17,$F$7:$F$127) | L17: =VLOOKUP(A17,$A$139:$AW$244,$K$1,FALSE) | M17: =L17-G17 | O17: =L17-B18 | Q17: =D18-F18 | S17: =J17-K17
A18: 投資、長期應收款、貸墊款及準備金 | B18: =SUM(臺大:東專!B17) | D18: =SUM(臺大:東專!D17) | F18: =SUM(臺大:東專!F17) | G18: =SUM(臺大:東專!G17) | H18: 機械及設備 | I18: 103 | J18: =SUM(臺大:東專!J17) | K18: =-SUMIF($C$7:$C$127,I18,$D$7:$D$127)+SUMIF($E$7:$E$127,I18,$F$7:$F$127) | L18: =VLOOKUP(A18,$A$139:$AW$244,$K$1,FALSE) | M18: =L18-G18 | O18: =L18-B19 | Q18: =D19-F19 | S18: =J18-K18
A19: 採權益法之投資 | B19: =SUM(臺大:東專!B18) | D19: =SUM(臺大:東專!D18) | F19: =SUM(臺大:東專!F18) | G19: =SUM(臺大:東專!G18) | H19: 交通及運輸設備 | I19: 104 | J19: =SUM(臺大:東專!J18) | K19: =-SUMIF($C$7:$C$127,I19,$D$7:$D$127)+SUMIF($E$7:$E$127,I19,$F$7:$F$127) | L19: =VLOOKUP(A19,$A$139:$AW$244,$K$1,FALSE) | M19: =L19-G19 | O19: =L19-B20 | Q19: =D20-F20 | S19: =J19-K19
A20: 非流動金融資產 | B20: =SUM(臺大:東專!B19) | C20: 241 | D20: =SUM(臺大:東專!D19) | E20: 221 | F20: =SUM(臺大:東專!F19) | G20: =SUM(臺大:東專!G19) | H20: 什項設備 | I20: 105 | J20: =SUM(臺大:東專!J19) | K20: =-SUMIF($C$7:$C$127,I20,$D$7:$D$127)+SUMIF($E$7:$E$127,I20,$F$7:$F$127) | L20: =VLOOKUP(A20,$A$139:$AW$244,$K$1,FALSE) | M20: =L20-G20 | O20: =L20-B21 | Q20: =D21-F21 | S20: =J20-K20
A21: 長期應收款 | B21: =SUM(臺大:東專!B20) | D21: =SUM(臺大:東專!D20) | F21: =SUM(臺大:東專!F20) | G21: =SUM(臺大:東專!G20) | H21: 租賃資產 | I21: 106 | J21: =SUM(臺大:東專!J20) | K21: =-SUMIF($C$7:$C$127,I21,$D$7:$D$127)+SUMIF($E$7:$E$127,I21,$F$7:$F$127) | L21: =VLOOKUP(A21,$A$139:$AW$244,$K$1,FALSE) | M21: =L21-G21 | O21: =L21-B22 | Q21: =D22-F22 | S21: =J21-K21
A22: 準備金 | B22: =SUM(臺大:東專!B21) | C22: 242 | D22: =SUM(臺大:東專!D21) | E22: 222 | F22: =SUM(臺大:東專!F21) | G22: =SUM(臺大:東專!G21) | H22: 租賃權益改良 | I22: 107 | J22: =SUM(臺大:東專!J21) | K22: =-SUMIF($C$7:$C$127,I22,$D$7:$D$127)+SUMIF($E$7:$E$127,I22,$F$7:$F$127) | L22: =VLOOKUP(A22,$A$139:$AW$244,$K$1,FALSE) | M22: =L22-G22 | O22: =L22-B23 | Q22: =D23-F23 | S22: =J22-K22
B23: =SUM(臺大:東專!B22) | C23: 401 | D23: =SUM(臺大:東專!D22) | E23: 402 | F23: =SUM(臺大:東專!F22) | G23: =SUM(臺大:東專!G22) | H23: 代管資產 | I23: 108 | J23: =SUM(臺大:東專!J22) | K23: =-SUMIF($C$7:$C$127,I23,$D$7:$D$127)+SUMIF($E$7:$E$127,I23,$F$7:$F$127) | O23: =L23-B24 | Q23: =D24-F24 | S23: =J23-K23
B24: =SUM(臺大:東專!B23) | C24: 403 | D24: =SUM(臺大:東專!D23) | F24: =SUM(臺大:東專!F23) | G24: =SUM(臺大:東專!G23) | H24: 生產性生物資產－非流動 | I24: 109 | J24: =SUM(臺大:東專!J23) | K24: =-SUMIF($C$7:$C$127,I24,$D$7:$D$127)+SUMIF($E$7:$E$127,I24,$F$7:$F$127) | O24: =L24-B25 | Q24: =D25-F25 | S24: =J24-K24
B25: =SUM(臺大:東專!B24) | C25: C | D25: =SUM(臺大:東專!D24) | F25: =SUM(臺大:東專!F24) | G25: =SUM(臺大:東專!G24) | H25: 攤銷 | J25: =SUM(臺大:東專!J24) | K25: =SUM(K26:K27) | O25: =L25-B26 | Q25: =D26-F26 | S25: =J25-K25
B26: =SUM(臺大:東專!B25) | C26: 125 | D26: =SUM(臺大:東專!D25) | F26: =SUM(臺大:東專!F25) | G26: =SUM(臺大:東專!G25) | H26: 攤銷電腦軟體 | I26: 111 | J26: =SUM(臺大:東專!J25) | K26: =-SUMIF($C$7:$C$127,I26,$D$7:$D$127)+SUMIF($E$7:$E$127,I26,$F$7:$F$127) | O26: =L26-B27 | Q26: =D27-F27 | S26: =J26-K26
A27: 不動產、廠房及設備 | B27: =SUM(臺大:東專!B26) | D27: =SUM(臺大:東專!D26) | F27: =SUM(臺大:東專!F26) | G27: =SUM(臺大:東專!G26) | H27: 其他攤銷費用 | I27: 112 | J27: =SUM(臺大:東專!J26) | K27: =-SUMIF($C$7:$C$127,I27,$D$7:$D$127)+SUMIF($E$7:$E$127,I27,$F$7:$F$127) | L27: =VLOOKUP(A27,$A$139:$AW$244,$K$1,FALSE) | M27: =L27-G27 | O27: =L27-B27 | Q27: =D27-F27 | S27: =J27-K27
A28: 土地 | B28: =SUM(臺大:東專!B27) | C28: 121 | D28: =SUM(臺大:東專!D27) | F28: =SUM(臺大:東專!F27) | G28: =SUM(臺大:東專!G27) | H28: 其他 | J28: =SUM(臺大:東專!J27) | K28: =K29+K30+K33 | L28: =VLOOKUP(A28,$A$139:$AW$244,$K$1,FALSE) | M28: =L28-G28 | O28: =L28-B28 | Q28: =D28-F28 | S28: =J28-K28
B29: =SUM(臺大:東專!B28) | D29: =SUM(臺大:東專!D28) | F29: =SUM(臺大:東專!F28) | G29: =SUM(臺大:東專!G28) | H29: 應付退休及離職金 | I29: 122 | J29: =SUM(臺大:東專!J28) | K29: =-SUMIF($C$7:$C$127,I29,$D$7:$D$127)+SUMIF($E$7:$E$127,I29,$F$7:$F$127) | O29: =L29-B29 | Q29: =D29-F29 | S29: =J29-K29
A30: 土地改良物 | B30: =SUM(臺大:東專!B29) | C30: 251 | D30: =SUM(臺大:東專!D29) | E30: 101 | F30: =SUM(臺大:東專!F29) | G30: =SUM(臺大:東專!G29) | H30: 遞延收入 | J30: =SUM(臺大:東專!J29) | K30: =K31+K32 | L30: =VLOOKUP(A30,$A$139:$AW$244,$K$1,FALSE) | M30: =L30-G30 | O30: =L30-B30 | Q30: =D30-F30 | S30: =J30-K30
B31: =SUM(臺大:東專!B30) | C31: 404 | D31: =SUM(臺大:東專!D30) | F31: =SUM(臺大:東專!F30) | G31: =SUM(臺大:東專!G30) | H31: 遞延收入-其他補助收入 | I31: 123 | J31: =SUM(臺大:東專!J30) | K31: =-SUMIF($C$7:$C$127,I31,$D$7:$D$127)+SUMIF($E$7:$E$127,I31,$F$7:$F$127) | O31: =L31-B31 | Q31: =D31-F31 | S31: =J31-K31
B32: =SUM(臺大:東專!B31) | D32: =SUM(臺大:東專!D31) | F32: =SUM(臺大:東專!F31) | G32: =SUM(臺大:東專!G31) | H32: 遞延收入-受贈收入 | I32: 124 | J32: =SUM(臺大:東專!J31) | K32: =-SUMIF($C$7:$C$127,I32,$D$7:$D$127)+SUMIF($E$7:$E$127,I32,$F$7:$F$127) | O32: =L32-B32 | Q32: =D32-F32 | S32: =J32-K32
B33: =SUM(臺大:東專!B32) | D33: =SUM(臺大:東專!D32) | F33: =SUM(臺大:東專!F32) | G33: =SUM(臺大:東專!G32) | H33: 其他 | I33: 125 | J33: =SUM(臺大:東專!J32) | K33: =-SUMIF($C$7:$C$127,I33,$D$7:$D$127)+SUMIF($E$7:$E$127,I33,$F$7:$F$127) | O33: =L33-B33 | Q33: =D33-F33 | S33: =J33-K33
A34: 房屋及建築 | B34: =SUM(臺大:東專!B33) | C34: 252 | D34: =SUM(臺大:東專!D33) | E34: 102 | F34: =SUM(臺大:東專!F33) | G34: =SUM(臺大:東專!G33) | H34: 流動資產淨減（淨增） | I34: 151 | J34: =SUM(臺大:東專!J33) | K34: =-SUMIF($C$7:$C$127,I34,$D$7:$D$127)+SUMIF($E$7:$E$127,I34,$F$7:$F$127) | L34: =VLOOKUP(A34,$A$139:$AW$244,$K$1,FALSE) | M34: =L34-G34 | O34: =L34-B34 | Q34: =D34-F34 | S34: =J34-K34
B35: =SUM(臺大:東專!B34) | C35: 405 | D35: =SUM(臺大:東專!D34) | F35: =SUM(臺大:東專!F34) | G35: =SUM(臺大:東專!G34) | H35: 流動負債淨增（淨減） | I35: 161 | J35: =SUM(臺大:東專!J34) | K35: =-SUMIF($C$7:$C$127,I35,$D$7:$D$127)+SUMIF($E$7:$E$127,I35,$F$7:$F$127) | O35: =L35-B35 | Q35: =D35-F35 | S35: =J35-K35
B36: =SUM(臺大:東專!B35) | D36: =SUM(臺大:東專!D35) | F36: =SUM(臺大:東專!F35) | G36: =SUM(臺大:東專!G35) | H36: 未計利息股利之現金流入（流出） | J36: =SUM(臺大:東專!J35) | K36: =K13+K14 | O36: =L36-B36 | Q36: =D36-F36 | S36: =J36-K36
B37: =SUM(臺大:東專!B36) | D37: =SUM(臺大:東專!D36) | F37: =SUM(臺大:東專!F36) | G37: =SUM(臺大:東專!G36) | H37: 收取利息 | J37: =SUM(臺大:東專!J36) | K37: =J37 | O37: =L37-B37 | Q37: =D37-F37 | S37: =J37-K37
A38: 機械及設備 | B38: =SUM(臺大:東專!B37) | C38: 253 | D38: =SUM(臺大:東專!D37) | E38: 103 | F38: =SUM(臺大:東專!F37) | G38: =SUM(臺大:東專!G37) | H38: 收取股利 | J38: =SUM(臺大:東專!J37) | K38: =J38 | L38: =VLOOKUP(A38,$A$139:$AW$244,$K$1,FALSE) | M38: =L38-G38 | O38: =L38-B38 | Q38: =D38-F38 | S38: =J38-K38
B39: =SUM(臺大:東專!B38) | C39: 407 | D39: =SUM(臺大:東專!D38) | F39: =SUM(臺大:東專!F38) | G39: =SUM(臺大:東專!G38) | H39: 支付利息 | J39: =SUM(臺大:東專!J38) | K39: =J39 | O39: =L39-B39 | Q39: =D39-F39 | S39: =J39-K39
B40: =SUM(臺大:東專!B39) | C40: 409 | D40: =SUM(臺大:東專!D39) | E40: 412 | F40: =SUM(臺大:東專!F39) | G40: =SUM(臺大:東專!G39) | H40: ▼業務活動之淨現金流入（流出） | J40: =SUM(臺大:東專!J39) | K40: =J40 | O40: =L40-B40 | Q40: =D40-F40 | S40: =J40-K40
...

Sheet 臺大
A1: =OFFSET(A139,0,K1-1) | K1: =L1+2 | L1: 1
A2: 預計平衡表與現金流量表勾稽底稿
A3: 中華民國115年度
A4: 科目 | B4: 114.12.31 | C4: 調整項目 | G4: 115.12.31 | H4: 現金流量表勾稽項目
B5: 預計數 | D5: 借方 | F5: 貸方 | G5: 預計數
A6: 資產 | H6: ▼業務活動之現金流量 | L6: 114年12月 | M6: 差異數要再加(減) | O6: 比較增減 | Q6: 調整項目
A7: 流動資產 | B7: =SUM(B8:B16) | G7: =SUM(G8:G16) | H7: 本期賸餘（短絀） | I7: A | J7: =OFFSET(A480,0,$K$1-1) | K7: =-SUMIF($C$7:$C$127,I7,$D$7:$D$127)+SUMIF($E$7:$E$127,I7,$F$7:$F$127) | L7: =VLOOKUP(A7,$A$140:$AX$249,$K$1,FALSE) | M7: =L7-G7 | O7: =L7-B7 | P7: =J7-K7 | Q7: =D7-F7
A8: 現金 | B8: =VLOOKUP(A8,$A$309:$AX$418,$K$1,FALSE) | C8: B | D8: =IF(G8-B8>0,G8-B8,"0") | E8: B | F8: =IF(G8-B8<0,B8-G8,"0") | G8: =J87 | H8: 利息股利之調整 | J8: =OFFSET(A481,0,$K$1-1) | K8: =SUM(K9:K11) | L8: =VLOOKUP(A8,$A$140:$AX$249,$K$1,FALSE) | M8: =L8-G8 | O8: =L8-B8 | P8: =J8-K8 | Q8: =D8-F8
A9: 流動金融資產 | B9: =VLOOKUP(A9,$A$309:$AX$418,$K$1,FALSE) | C9: 231 | D9: =J50*-1 | E9: 211 | F9: =J42 | G9: =B9+D9-F9+D10-F10 | H9: 利息收入 | J9: =OFFSET(A482,0,$K$1-1) | K9: =J9 | L9: =VLOOKUP(A9,$A$140:$AX$249,$K$1,FALSE) | M9: =L9-G9 | O9: =L9-B9 | P9: =J9-K9 | Q9: =D9-F9
C10: 125 | H10: 股利收入 | J10: =OFFSET(A483,0,$K$1-1) | K10: =J10 | M10: =L10-G10 | O10: =L10-B10 | P10: =J10-K10 | Q10: =D10-F10
A11: 應收款項 | B11: =VLOOKUP(A11,$A$309:$AX$418,$K$1,FALSE) | C11: 151 | E11: 151 | G11: =B11+D11-F11 | H11: 利息費用 | J11: =OFFSET(A484,0,$K$1-1) | K11: =J11 | L11: =VLOOKUP(A11,$A$140:$AX$249,$K$1,FALSE) | M11: =L11-G11 | O11: =L11-B11 | P11: =J11-K11 | Q11: =D11-F11
A12: 0 | H12: 未計利息股利之本期賸餘（短絀） | J12: =OFFSET(A485,0,$K$1-1) | K12: =K7+K8 | M12: =L12-G12 | O12: =L12-B12 | P12: =J12-K12 | Q12: =D12-F12
A13: 存貨 | B13: =VLOOKUP(A13,$A$309:$AX$418,$K$1,FALSE) | C13: 151 | E13: 151 | G13: =B13+D13-F13 | H13: 調整項目 | J13: =OFFSET(A486,0,$K$1-1) | K13: =SUM(K14,K24,K27,K34,K33) | L13: =VLOOKUP(A13,$A$140:$AX$249,$K$1,FALSE) | M13: =L13-G13 | O13: =L13-B13 | P13: =J13-K13 | Q13: =D13-F13
A14: 生產性生物資產－流動 | B14: =VLOOKUP(A14,$A$309:$AX$418,$K$1,FALSE) | C14: 151 | E14: 151 | G14: =B14+D14-F14 | H14: 折舊、減損及折耗 | J14: =OFFSET(A487,0,$K$1-1) | K14: =SUM(K15:K23) | L14: =VLOOKUP(A14,$A$140:$AX$249,$K$1,FALSE) | M14: =L14-G14 | O14: =L14-B14 | P14: =J14-K14 | Q14: =D14-F14
A15: 預付款項 | B15: =VLOOKUP(A15,$A$309:$AX$418,$K$1,FALSE) | C15: 151 | E15: 151 | G15: =B15+D15-F15 | H15: 土地改良物 | I15: 101 | J15: =OFFSET(A488,0,$K$1-1) | K15: =-SUMIF($C$7:$C$127,I15,$D$7:$D$127)+SUMIF($E$7:$E$127,I15,$F$7:$F$127) | L15: =VLOOKUP(A15,$A$140:$AX$249,$K$1,FALSE) | M15: =L15-G15 | O15: =L15-B15 | P15: =J15-K15 | Q15: =D15-F15
A16: 短期貸墊款 | B16: =VLOOKUP(A16,$A$309:$AX$418,$K$1,FALSE) | C16: 151 | E16: 212 | F16: =J43 | G16: =B16+D16-F16 | H16: 房屋及建築 | I16: 102 | J16: =OFFSET(A489,0,$K$1-1) | K16: =-SUMIF($C$7:$C$127,I16,$D$7:$D$127)+SUMIF($E$7:$E$127,I16,$F$7:$F$127) | L16: =VLOOKUP(A16,$A$140:$AX$249,$K$1,FALSE) | M16: =L16-G16 | O16: =L16-B16 | P16: =J16-K16 | Q16: =D16-F16
A17: 投資、長期應收款、貸墊款及準備金 | B17: =SUM(B18:B21) | G17: =SUM(G18:G21) | H17: 機械及設備 | I17: 103 | J17: =OFFSET(A490,0,$K$1-1) | K17: =-SUMIF($C$7:$C$127,I17,$D$7:$D$127)+SUMIF($E$7:$E$127,I17,$F$7:$F$127) | L17: =VLOOKUP(A17,$A$140:$AX$249,$K$1,FALSE) | M17: =L17-G17 | O17: =L17-B17 | P17: =J17-K17 | Q17: =D17-F17
A18: 採權益法之投資 | B18: =VLOOKUP(A18,$A$309:$AX$418,$K$1,FALSE) | G18: =D18+F18+B18 | H18: 交通及運輸設備 | I18: 104 | J18: =OFFSET(A491,0,$K$1-1) | K18: =-SUMIF($C$7:$C$127,I18,$D$7:$D$127)+SUMIF($E$7:$E$127,I18,$F$7:$F$127) | L18: =VLOOKUP(A18,$A$140:$AX$249,$K$1,FALSE) | M18: =L18-G18 | O18: =L18-B18 | P18: =J18-K18 | Q18: =D18-F18
A19: 非流動金融資產 | B19: =VLOOKUP(A19,$A$309:$AX$418,$K$1,FALSE) | C19: 241 | D19: =J52*-1 | E19: 221 | F19: =J45 | G19: =B19+D19-F19 | H19: 什項設備 | I19: 105 | J19: =OFFSET(A492,0,$K$1-1) | K19: =-SUMIF($C$7:$C$127,I19,$D$7:$D$127)+SUMIF($E$7:$E$127,I19,$F$7:$F$127) | L19: =VLOOKUP(A19,$A$140:$AX$249,$K$1,FALSE) | M19: =L19-G19 | O19: =L19-B19 | P19: =J19-K19 | Q19: =D19-F19
A20: 長期應收款 | B20: =VLOOKUP(A20,$A$309:$AX$418,$K$1,FALSE) | G20: =B20+D20-F20 | H20: 租賃資產 | I20: 106 | J20: =OFFSET(A493,0,$K$1-1) | K20: =-SUMIF($C$7:$C$127,I20,$D$7:$D$127)+SUMIF($E$7:$E$127,I20,$F$7:$F$127) | L20: =VLOOKUP(A20,$A$140:$AX$249,$K$1,FALSE) | M20: =L20-G20 | O20: =L20-B20 | P20: =J20-K20 | Q20: =D20-F20
A21: 準備金 | B21: =VLOOKUP(A21,$A$309:$AX$418,$K$1,FALSE) | C21: 242 | D21: =J53*-1 | E21: 222 | F21: =J46 | G21: =B21+SUM(D21:D25)-SUM(F21:F25) | H21: 租賃權益改良 | I21: 107 | J21: =OFFSET(A494,0,$K$1-1) | K21: =-SUMIF($C$7:$C$127,I21,$D$7:$D$127)+SUMIF($E$7:$E$127,I21,$F$7:$F$127) | L21: =VLOOKUP(A21,$A$140:$AX$249,$K$1,FALSE) | M21: =L21-G21 | O21: =L21-B21 | P21: =J21-K21 | Q21: =D21-F21
A22: 0 | C22: 401 | D22: =J90 | E22: 402 | F22: =-J91 | H22: 代管資產 | I22: 108 | J22: =OFFSET(A495,0,$K$1-1) | K22: =-SUMIF($C$7:$C$127,I22,$D$7:$D$127)+SUMIF($E$7:$E$127,I22,$F$7:$F$127) | M22: =L22-G22 | O22: =L22-B22 | P22: =J22-K22 | Q22: =D22-F22
A23: 0 | C23: 403 | D23: =J93 | H23: 生產性生物資產－非流動 | I23: 109 | J23: =OFFSET(A496,0,$K$1-1) | K23: =-SUMIF($C$7:$C$127,I23,$D$7:$D$127)+SUMIF($E$7:$E$127,I23,$F$7:$F$127) | M23: =L23-G23 | O23: =L23-B23 | P23: =J23-K23 | Q23: =D23-F23
A24: 0 | H24: 攤銷 | J24: =OFFSET(A497,0,$K$1-1) | K24: =SUM(K25:K26) | M24: =L24-G24 | O24: =L24-B24 | P24: =J24-K24 | Q24: =D24-F24
C25: 125 | D25: =J32*-1 | H25: 攤銷電腦軟體 | I25: 111 | J25: =OFFSET(A498,0,$K$1-1) | K25: =-SUMIF($C$7:$C$127,I25,$D$7:$D$127)+SUMIF($E$7:$E$127,I25,$F$7:$F$127) | M25: =L25-G25 | O25: =L25-B25 | P25: =J25-K25 | Q25: =D25-F25
A26: 不動產、廠房及設備 | B26: =SUM(B27:B52) | G26: =SUM(G27:G52) | H26: 其他攤銷費用 | I26: 112 | J26: =OFFSET(A499,0,$K$1-1) | K26: =-SUMIF($C$7:$C$127,I26,$D$7:$D$127)+SUMIF($E$7:$E$127,I26,$F$7:$F$127) | L26: =VLOOKUP(A26,$A$140:$AX$249,$K$1,FALSE) | M26: =L26-G26 | O26: =L26-B26 | P26: =J26-K26 | Q26: =D26-F26
A27: 土地 | B27: =VLOOKUP(A27,$A$309:$AX$418,$K$1,FALSE) | C27: 121 | G27: =B27+SUM(D27)-SUM(F27) | H27: 其他 | J27: =OFFSET(A500,0,$K$1-1) | K27: =K28+K29+K32 | L27: =VLOOKUP(A27,$A$140:$AX$249,$K$1,FALSE) | M27: =L27-G27 | O27: =L27-B27 | P27: =J27-K27 | Q27: =D27-F27
A28: 0 | H28: 應付退休及離職金 | I28: 122 | J28: =OFFSET(A501,0,$K$1-1) | K28: =-SUMIF($C$7:$C$127,I28,$D$7:$D$127)+SUMIF($E$7:$E$127,I28,$F$7:$F$127) | M28: =L28-G28 | O28: =L28-B28 | P28: =J28-K28 | Q28: =D28-F28
A29: 土地改良物 | B29: =VLOOKUP(A29,$A$309:$AX$418,$K$1,FALSE) | C29: 251 | D29: =J57*-1 | E29: 101 | F29: =J15 | G29: =B29+SUM(D29:D32)-SUM(F29:F32) | H29: 遞延收入 | J29: =OFFSET(A502,0,$K$1-1) | K29: =SUM(K30:K31) | L29: =VLOOKUP(A29,$A$140:$AX$249,$K$1,FALSE) | M29: =L29-G29 | O29: =L29-B29 | P29: =J29-K29 | Q29: =D29-F29
A30: 0 | C30: 404 | D30: =J96 | H30: 遞延收入-其他補助收入 | I30: 123 | J30: =OFFSET(A503,0,$K$1-1) | K30: =-SUMIF($C$7:$C$127,I30,$D$7:$D$127)+SUMIF($E$7:$E$127,I30,$F$7:$F$127) | M30: =L30-G30 | O30: =L30-B30 | P30: =J30-K30 | Q30: =D30-F30
A31: 0 | H31: 遞延收入-受贈收入 | I31: 124 | J31: =OFFSET(A504,0,$K$1-1) | K31: =-SUMIF($C$7:$C$127,I31,$D$7:$D$127)+SUMIF($E$7:$E$127,I31,$F$7:$F$127) | M31: =L31-G31 | O31: =L31-B31 | P31: =J31-K31 | Q31: =D31-F31
A32: 0 | H32: 其他 | I32: 125 | J32: =OFFSET(A505,0,$K$1-1) | M32: =L32-G32 | O32: =L32-B32 | P32: =J32-K32 | Q32: =D32-F32
A33: 房屋及建築 | B33: =VLOOKUP(A33,$A$309:$AX$418,$K$1,FALSE) | C33: 252 | D33: =J58*-1 | E33: 102 | F33: =J16 | G33: =B33+SUM(D33:D36)-SUM(F33:F36) | H33: 流動資產淨減（淨增） | I33: 151 | J33: =OFFSET(A506,0,$K$1-1) | K33: =-SUMIF($C$7:$C$127,I33,$D$7:$D$127)+SUMIF($E$7:$E$127,I33,$F$7:$F$127) | L33: =VLOOKUP(A33,$A$140:$AX$249,$K$1,FALSE) | M33: =L33-G33 | O33: =L33-B33 | P33: =J33-K33 | Q33: =D33-F33
A34: 0 | C34: 405 | D34: =J97 | H34: 流動負債淨增（淨減） | I34: 161 | J34: =OFFSET(A507,0,$K$1-1) | K34: =-SUMIF($C$7:$C$127,I34,$D$7:$D$127)+SUMIF($E$7:$E$127,I34,$F$7:$F$127) | M34: =L34-G34 | O34: =L34-B34 | P34: =J34-K34 | Q34: =D34-F34
A35: 0 | H35: 未計利息股利之現金流入（流出） | J35: =OFFSET(A508,0,$K$1-1) | K35: =K12+K13 | M35: =L35-G35 | O35: =L35-B35 | P35: =J35-K35 | Q35: =D35-F35
A36: 0 | H36: 收取利息 | J36: =OFFSET(A509,0,$K$1-1) | K36: =J36 | M36: =L36-G36 | O36: =L36-B36 | P36: =J36-K36 | Q36: =D36-F36
A37: 機械及設備 | B37: =VLOOKUP(A37,$A$309:$AX$418,$K$1,FALSE) | C37: 253 | D37: =J59*-1 | E37: 103 | F37: =J17 | G37: =B37+SUM(D37:D41)-SUM(F37:F41) | H37: 收取股利 | J37: =OFFSET(A510,0,$K$1-1) | K37: =J37 | L37: =VLOOKUP(A37,$A$140:$AX$249,$K$1,FALSE) | M37: =L37-G37 | O37: =L37-B37 | P37: =J37-K37 | Q37: =D37-F37
A38: 0 | C38: 407 | D38: =J101 | H38: 支付利息 | J38: =OFFSET(A511,0,$K$1-1) | K38: =J38 | M38: =L38-G38 | O38: =L38-B38 | P38: =J38-K38 | Q38: =D38-F38
A39: 0 | C39: 409 | D39: =J105 | E39: 412 | F39: =-J109 | H39: ▼業務活動之淨現金流入（流出） | J39: =OFFSET(A512,0,$K$1-1) | K39: =K36+K37+K38+K35 | M39: =L39-G39 | O39: =L39-B39 | P39: =J39-K39 | Q39: =D39-F39
A40: 0 | H40: ▼投資活動之現金流量 | J40: =OFFSET(A513,0,$K$1-1) | K40: =SUM(K41,K44,K47,K48,K49,K51,K54,K64) | M40: =L40-G40 | O40: =L40-B40 | P40: =J40-K40 | Q40: =D40-F40
...

Sheet 政大
A1: =OFFSET(A139,0,K1-1) | K1: =L1+2 | L1: 2
A2: 預計平衡表與現金流量表勾稽底稿
A3: 中華民國115年度
A4: 科目 | B4: 114.12.31 | C4: 調整項目 | G4: 115.12.31 | H4: 現金流量表勾稽項目
B5: 預計數 | D5: 借方 | F5: 貸方 | G5: 預計數
A6: 資產 | H6: ▼業務活動之現金流量 | L6: 114年12月 | M6: 差異數要再加(減) | O6: 比較增減 | Q6: 調整項目
A7: 流動資產 | B7: =SUM(B8:B16) | G7: =SUM(G8:G16) | H7: 本期賸餘（短絀） | I7: A | J7: =OFFSET(A480,0,$K$1-1) | K7: =-SUMIF($C$7:$C$127,I7,$D$7:$D$127)+SUMIF($E$7:$E$127,I7,$F$7:$F$127) | L7: =VLOOKUP(A7,$A$140:$AX$249,$K$1,FALSE) | M7: =L7-G7 | O7: =L7-B7 | P7: =J7-K7 | Q7: =D7-F7
A8: 現金 | B8: =VLOOKUP(A8,$A$309:$AX$418,$K$1,FALSE) | C8: B | D8: =IF(G8-B8>0,G8-B8,"0") | E8: B | F8: =IF(G8-B8<0,B8-G8,"0") | G8: =J87 | H8: 利息股利之調整 | J8: =OFFSET(A481,0,$K$1-1) | K8: =SUM(K9:K11) | L8: =VLOOKUP(A8,$A$140:$AX$249,$K$1,FALSE) | M8: =L8-G8 | O8: =L8-B8 | P8: =J8-K8 | Q8: =D8-F8
A9: 流動金融資產 | B9: =VLOOKUP(A9,$A$309:$AX$418,$K$1,FALSE) | C9: 231 | D9: =J50*-1 | E9: 211 | F9: =J42 | G9: =B9+D9-F9+D10-F10 | H9: 利息收入 | J9: =OFFSET(A482,0,$K$1-1) | K9: =J9 | L9: =VLOOKUP(A9,$A$140:$AX$249,$K$1,FALSE) | M9: =L9-G9 | O9: =L9-B9 | P9: =J9-K9 | Q9: =D9-F9
C10: 125 | H10: 股利收入 | J10: =OFFSET(A483,0,$K$1-1) | K10: =J10 | M10: =L10-G10 | O10: =L10-B10 | P10: =J10-K10 | Q10: =D10-F10
A11: 應收款項 | B11: =VLOOKUP(A11,$A$309:$AX$418,$K$1,FALSE) | C11: 151 | E11: 151 | G11: =B11+D11-F11 | H11: 利息費用 | J11: =OFFSET(A484,0,$K$1-1) | K11: =J11 | L11: =VLOOKUP(A11,$A$140:$AX$249,$K$1,FALSE) | M11: =L11-G11 | O11: =L11-B11 | P11: =J11-K11 | Q11: =D11-F11
A12: 0 | H12: 未計利息股利之本期賸餘（短絀） | J12: =OFFSET(A485,0,$K$1-1) | K12: =K7+K8 | M12: =L12-G12 | O12: =L12-B12 | P12: =J12-K12 | Q12: =D12-F12
A13: 存貨 | B13: =VLOOKUP(A13,$A$309:$AX$418,$K$1,FALSE) | C13: 151 | E13: 151 | G13: =B13+D13-F13 | H13: 調整項目 | J13: =OFFSET(A486,0,$K$1-1) | K13: =SUM(K14,K24,K27,K34,K33) | L13: =VLOOKUP(A13,$A$140:$AX$249,$K$1,FALSE) | M13: =L13-G13 | O13: =L13-B13 | P13: =J13-K13 | Q13: =D13-F13
A14: 生產性生物資產－流動 | B14: =VLOOKUP(A14,$A$309:$AX$418,$K$1,FALSE) | C14: 151 | E14: 151 | G14: =B14+D14-F14 | H14: 折舊、減損及折耗 | J14: =OFFSET(A487,0,$K$1-1) | K14: =SUM(K15:K23) | L14: =VLOOKUP(A14,$A$140:$AX$249,$K$1,FALSE) | M14: =L14-G14 | O14: =L14-B14 | P14: =J14-K14 | Q14: =D14-F14
A15: 預付款項 | B15: =VLOOKUP(A15,$A$309:$AX$418,$K$1,FALSE) | C15: 151 | E15: 151 | G15: =B15+D15-F15 | H15: 土地改良物 | I15: 101 | J15: =OFFSET(A488,0,$K$1-1) | K15: =-SUMIF($C$7:$C$127,I15,$D$7:$D$127)+SUMIF($E$7:$E$127,I15,$F$7:$F$127) | L15: =VLOOKUP(A15,$A$140:$AX$249,$K$1,FALSE) | M15: =L15-G15 | O15: =L15-B15 | P15: =J15-K15 | Q15: =D15-F15
A16: 短期貸墊款 | B16: =VLOOKUP(A16,$A$309:$AX$418,$K$1,FALSE) | C16: 151 | E16: 212 | F16: =J43 | G16: =B16+D16-F16 | H16: 房屋及建築 | I16: 102 | J16: =OFFSET(A489,0,$K$1-1) | K16: =-SUMIF($C$7:$C$127,I16,$D$7:$D$127)+SUMIF($E$7:$E$127,I16,$F$7:$F$127) | L16: =VLOOKUP(A16,$A$140:$AX$249,$K$1,FALSE) | M16: =L16-G16 | O16: =L16-B16 | P16: =J16-K16 | Q16: =D16-F16
A17: 投資、長期應收款、貸墊款及準備金 | B17: =SUM(B18:B21) | G17: =SUM(G18:G21) | H17: 機械及設備 | I17: 103 | J17: =OFFSET(A490,0,$K$1-1) | K17: =-SUMIF($C$7:$C$127,I17,$D$7:$D$127)+SUMIF($E$7:$E$127,I17,$F$7:$F$127) | L17: =VLOOKUP(A17,$A$140:$AX$249,$K$1,FALSE) | M17: =L17-G17 | O17: =L17-B17 | P17: =J17-K17 | Q17: =D17-F17
A18: 採權益法之投資 | B18: =VLOOKUP(A18,$A$309:$AX$418,$K$1,FALSE) | G18: =D18+F18+B18 | H18: 交通及運輸設備 | I18: 104 | J18: =OFFSET(A491,0,$K$1-1) | K18: =-SUMIF($C$7:$C$127,I18,$D$7:$D$127)+SUMIF($E$7:$E$127,I18,$F$7:$F$127) | L18: =VLOOKUP(A18,$A$140:$AX$249,$K$1,FALSE) | M18: =L18-G18 | O18: =L18-B18 | P18: =J18-K18 | Q18: =D18-F18
A19: 非流動金融資產 | B19: =VLOOKUP(A19,$A$309:$AX$418,$K$1,FALSE) | C19: 241 | D19: =J52*-1 | E19: 221 | F19: =J45 | G19: =B19+D19-F19 | H19: 什項設備 | I19: 105 | J19: =OFFSET(A492,0,$K$1-1) | K19: =-SUMIF($C$7:$C$127,I19,$D$7:$D$127)+SUMIF($E$7:$E$127,I19,$F$7:$F$127) | L19: =VLOOKUP(A19,$A$140:$AX$249,$K$1,FALSE) | M19: =L19-G19 | O19: =L19-B19 | P19: =J19-K19 | Q19: =D19-F19
A20: 長期應收款 | B20: =VLOOKUP(A20,$A$309:$AX$418,$K$1,FALSE) | G20: =B20+D20-F20 | H20: 租賃資產 | I20: 106 | J20: =OFFSET(A493,0,$K$1-1) | K20: =-SUMIF($C$7:$C$127,I20,$D$7:$D$127)+SUMIF($E$7:$E$127,I20,$F$7:$F$127) | L20: =VLOOKUP(A20,$A$140:$AX$249,$K$1,FALSE) | M20: =L20-G20 | O20: =L20-B20 | P20: =J20-K20 | Q20: =D20-F20
A21: 準備金 | B21: =VLOOKUP(A21,$A$309:$AX$418,$K$1,FALSE) | C21: 242 | D21: =J53*-1 | E21: 222 | F21: =J46 | G21: =B21+SUM(D21:D25)-SUM(F21:F25) | H21: 租賃權益改良 | I21: 107 | J21: =OFFSET(A494,0,$K$1-1) | K21: =-SUMIF($C$7:$C$127,I21,$D$7:$D$127)+SUMIF($E$7:$E$127,I21,$F$7:$F$127) | L21: =VLOOKUP(A21,$A$140:$AX$249,$K$1,FALSE) | M21: =L21-G21 | O21: =L21-B21 | P21: =J21-K21 | Q21: =D21-F21
A22: 0 | C22: 401 | D22: =J90 | E22: 402 | F22: =-J91 | H22: 代管資產 | I22: 108 | J22: =OFFSET(A495,0,$K$1-1) | K22: =-SUMIF($C$7:$C$127,I22,$D$7:$D$127)+SUMIF($E$7:$E$127,I22,$F$7:$F$127) | M22: =L22-G22 | O22: =L22-B22 | P22: =J22-K22 | Q22: =D22-F22
A23: 0 | C23: 403 | D23: =J93 | H23: 生產性生物資產－非流動 | I23: 109 | J23: =OFFSET(A496,0,$K$1-1) | K23: =-SUMIF($C$7:$C$127,I23,$D$7:$D$127)+SUMIF($E$7:$E$127,I23,$F$7:$F$127) | M23: =L23-G23 | O23: =L23-B23 | P23: =J23-K23 | Q23: =D23-F23
A24: 0 | H24: 攤銷 | J24: =OFFSET(A497,0,$K$1-1) | K24: =SUM(K25:K26) | M24: =L24-G24 | O24: =L24-B24 | P24: =J24-K24 | Q24: =D24-F24
C25: 125 | D25: =J32*-1 | H25: 攤銷電腦軟體 | I25: 111 | J25: =OFFSET(A498,0,$K$1-1) | K25: =-SUMIF($C$7:$C$127,I25,$D$7:$D$127)+SUMIF($E$7:$E$127,I25,$F$7:$F$127) | M25: =L25-G25 | O25: =L25-B25 | P25: =J25-K25 | Q25: =D25-F25
A26: 不動產、廠房及設備 | B26: =SUM(B27:B52) | G26: =SUM(G27:G52) | H26: 其他攤銷費用 | I26: 112 | J26: =OFFSET(A499,0,$K$1-1) | K26: =-SUMIF($C$7:$C$127,I26,$D$7:$D$127)+SUMIF($E$7:$E$127,I26,$F$7:$F$127) | L26: =VLOOKUP(A26,$A$140:$AX$249,$K$1,FALSE) | M26: =L26-G26 | O26: =L26-B26 | P26: =J26-K26 | Q26: =D26-F26
A27: 土地 | B27: =VLOOKUP(A27,$A$309:$AX$418,$K$1,FALSE) | C27: 121 | G27: =B27+SUM(D27)-SUM(F27) | H27: 其他 | J27: =OFFSET(A500,0,$K$1-1) | K27: =K28+K29+K32 | L27: =VLOOKUP(A27,$A$140:$AX$249,$K$1,FALSE) | M27: =L27-G27 | O27: =L27-B27 | P27: =J27-K27 | Q27: =D27-F27
A28: 0 | H28: 應付退休及離職金 | I28: 122 | J28: =OFFSET(A501,0,$K$1-1) | K28: =-SUMIF($C$7:$C$127,I28,$D$7:$D$127)+SUMIF($E$7:$E$127,I28,$F$7:$F$127) | M28: =L28-G28 | O28: =L28-B28 | P28: =J28-K28 | Q28: =D28-F28
A29: 土地改良物 | B29: =VLOOKUP(A29,$A$309:$AX$418,$K$1,FALSE) | C29: 251 | D29: =J57*-1 | E29: 101 | F29: =J15 | G29: =B29+SUM(D29:D32)-SUM(F29:F32) | H29: 遞延收入 | J29: =OFFSET(A502,0,$K$1-1) | K29: =SUM(K30:K31) | L29: =VLOOKUP(A29,$A$140:$AX$249,$K$1,FALSE) | M29: =L29-G29 | O29: =L29-B29 | P29: =J29-K29 | Q29: =D29-F29
A30: 0 | C30: 404 | D30: =J96 | H30: 遞延收入-其他補助收入 | I30: 123 | J30: =OFFSET(A503,0,$K$1-1) | K30: =-SUMIF($C$7:$C$127,I30,$D$7:$D$127)+SUMIF($E$7:$E$127,I30,$F$7:$F$127) | M30: =L30-G30 | O30: =L30-B30 | P30: =J30-K30 | Q30: =D30-F30
A31: 0 | H31: 遞延收入-受贈收入 | I31: 124 | J31: =OFFSET(A504,0,$K$1-1) | K31: =-SUMIF($C$7:$C$127,I31,$D$7:$D$127)+SUMIF($E$7:$E$127,I31,$F$7:$F$127) | M31: =L31-G31 | O31: =L31-B31 | P31: =J31-K31 | Q31: =D31-F31
A32: 0 | H32: 其他 | I32: 125 | J32: =OFFSET(A505,0,$K$1-1) | M32: =L32-G32 | O32: =L32-B32 | P32: =J32-K32 | Q32: =D32-F32
A33: 房屋及建築 | B33: =VLOOKUP(A33,$A$309:$AX$418,$K$1,FALSE) | C33: 252 | D33: =J58*-1 | E33: 102 | F33: =J16 | G33: =B33+SUM(D33:D36)-SUM(F33:F36) | H33: 流動資產淨減（淨增） | I33: 151 | J33: =OFFSET(A506,0,$K$1-1) | K33: =-SUMIF($C$7:$C$127,I33,$D$7:$D$127)+SUMIF($E$7:$E$127,I33,$F$7:$F$127) | L33: =VLOOKUP(A33,$A$140:$AX$249,$K$1,FALSE) | M33: =L33-G33 | O33: =L33-B33 | P33: =J33-K33 | Q33: =D33-F33
A34: 0 | C34: 405 | D34: =J97 | H34: 流動負債淨增（淨減） | I34: 161 | J34: =OFFSET(A507,0,$K$1-1) | K34: =-SUMIF($C$7:$C$127,I34,$D$7:$D$127)+SUMIF($E$7:$E$127,I34,$F$7:$F$127) | M34: =L34-G34 | O34: =L34-B34 | P34: =J34-K34 | Q34: =D34-F34
A35: 0 | H35: 未計利息股利之現金流入（流出） | J35: =OFFSET(A508,0,$K$1-1) | K35: =K12+K13 | M35: =L35-G35 | O35: =L35-B35 | P35: =J35-K35 | Q35: =D35-F35
A36: 0 | H36: 收取利息 | J36: =OFFSET(A509,0,$K$1-1) | K36: =J36 | M36: =L36-G36 | O36: =L36-B36 | P36: =J36-K36 | Q36: =D36-F36
A37: 機械及設備 | B37: =VLOOKUP(A37,$A$309:$AX$418,$K$1,FALSE) | C37: 253 | D37: =J59*-1 | E37: 103 | F37: =J17 | G37: =B37+SUM(D37:D41)-SUM(F37:F41) | H37: 收取股利 | J37: =OFFSET(A510,0,$K$1-1) | K37: =J37 | L37: =VLOOKUP(A37,$A$140:$AX$249,$K$1,FALSE) | M37: =L37-G37 | O37: =L37-B37 | P37: =J37-K37 | Q37: =D37-F37
A38: 0 | C38: 407 | D38: =J101 | H38: 支付利息 | J38: =OFFSET(A511,0,$K$1-1) | K38: =J38 | M38: =L38-G38 | O38: =L38-B38 | P38: =J38-K38 | Q38: =D38-F38
A39: 0 | C39: 409 | D39: =J105 | E39: 412 | F39: =-J109 | H39: ▼業務活動之淨現金流入（流出） | J39: =OFFSET(A512,0,$K$1-1) | K39: =K36+K37+K38+K35 | M39: =L39-G39 | O39: =L39-B39 | P39: =J39-K39 | Q39: =D39-F39
A40: 0 | H40: ▼投資活動之現金流量 | J40: =OFFSET(A513,0,$K$1-1) | K40: =SUM(K41,K44,K47,K48,K49,K51,K54,K64) | M40: =L40-G40 | O40: =L40-B40 | P40: =J40-K40 | Q40: =D40-F40
...

Sheet 清大
A1: =OFFSET(A139,0,K1-1) | K1: =L1+2 | L1: 3
A2: 預計平衡表與現金流量表勾稽底稿
A3: 中華民國115年度
A4: 科目 | B4: 114.12.31 | C4: 調整項目 | G4: 115.12.31 | H4: 現金流量表勾稽項目
B5: 預計數 | D5: 借方 | F5: 貸方 | G5: 預計數
A6: 資產 | H6: ▼業務活動之現金流量 | L6: 114年12月 | M6: 差異數要再加(減) | O6: 比較增減 | Q6: 調整項目
A7: 流動資產 | B7: =SUM(B8:B16) | G7: =SUM(G8:G16) | H7: 本期賸餘（短絀） | I7: A | J7: =OFFSET(A480,0,$K$1-1) | K7: =-SUMIF($C$7:$C$127,I7,$D$7:$D$127)+SUMIF($E$7:$E$127,I7,$F$7:$F$127) | L7: =VLOOKUP(A7,$A$140:$AX$249,$K$1,FALSE) | M7: =L7-G7 | O7: =L7-B7 | P7: =J7-K7 | Q7: =D7-F7
A8: 現金 | B8: =VLOOKUP(A8,$A$309:$AX$418,$K$1,FALSE) | C8: B | D8: =IF(G8-B8>0,G8-B8,"0") | E8: B | F8: =IF(G8-B8<0,B8-G8,"0") | G8: =J87 | H8: 利息股利之調整 | J8: =OFFSET(A481,0,$K$1-1) | K8: =SUM(K9:K11) | L8: =VLOOKUP(A8,$A$140:$AX$249,$K$1,FALSE) | M8: =L8-G8 | O8: =L8-B8 | P8: =J8-K8 | Q8: =D8-F8
A9: 流動金融資產 | B9: =VLOOKUP(A9,$A$309:$AX$418,$K$1,FALSE) | C9: 231 | D9: =J50*-1 | E9: 211 | F9: =J42 | G9: =B9+D9-F9+D10-F10 | H9: 利息收入 | J9: =OFFSET(A482,0,$K$1-1) | K9: =J9 | L9: =VLOOKUP(A9,$A$140:$AX$249,$K$1,FALSE) | M9: =L9-G9 | O9: =L9-B9 | P9: =J9-K9 | Q9: =D9-F9
C10: 125 | H10: 股利收入 | J10: =OFFSET(A483,0,$K$1-1) | K10: =J10 | M10: =L10-G10 | O10: =L10-B10 | P10: =J10-K10 | Q10: =D10-F10
A11: 應收款項 | B11: =VLOOKUP(A11,$A$309:$AX$418,$K$1,FALSE) | C11: 151 | E11: 151 | G11: =B11+D11-F11 | H11: 利息費用 | J11: =OFFSET(A484,0,$K$1-1) | K11: =J11 | L11: =VLOOKUP(A11,$A$140:$AX$249,$K$1,FALSE) | M11: =L11-G11 | O11: =L11-B11 | P11: =J11-K11 | Q11: =D11-F11
A12: 0 | H12: 未計利息股利之本期賸餘（短絀） | J12: =OFFSET(A485,0,$K$1-1) | K12: =K7+K8 | M12: =L12-G12 | O12: =L12-B12 | P12: =J12-K12 | Q12: =D12-F12
A13: 存貨 | B13: =VLOOKUP(A13,$A$309:$AX$418,$K$1,FALSE) | C13: 151 | E13: 151 | G13: =B13+D13-F13 | H13: 調整項目 | J13: =OFFSET(A486,0,$K$1-1) | K13: =SUM(K14,K24,K27,K34,K33) | L13: =VLOOKUP(A13,$A$140:$AX$249,$K$1,FALSE) | M13: =L13-G13 | O13: =L13-B13 | P13: =J13-K13 | Q13: =D13-F13
A14: 生產性生物資產－流動 | B14: =VLOOKUP(A14,$A$309:$AX$418,$K$1,FALSE) | C14: 151 | E14: 151 | G14: =B14+D14-F14 | H14: 折舊、減損及折耗 | J14: =OFFSET(A487,0,$K$1-1) | K14: =SUM(K15:K23) | L14: =VLOOKUP(A14,$A$140:$AX$249,$K$1,FALSE) | M14: =L14-G14 | O14: =L14-B14 | P14: =J14-K14 | Q14: =D14-F14
A15: 預付款項 | B15: =VLOOKUP(A15,$A$309:$AX$418,$K$1,FALSE) | C15: 151 | E15: 151 | G15: =B15+D15-F15 | H15: 土地改良物 | I15: 101 | J15: =OFFSET(A488,0,$K$1-1) | K15: =-SUMIF($C$7:$C$127,I15,$D$7:$D$127)+SUMIF($E$7:$E$127,I15,$F$7:$F$127) | L15: =VLOOKUP(A15,$A$140:$AX$249,$K$1,FALSE) | M15: =L15-G15 | O15: =L15-B15 | P15: =J15-K15 | Q15: =D15-F15
A16: 短期貸墊款 | B16: =VLOOKUP(A16,$A$309:$AX$418,$K$1,FALSE) | C16: 151 | E16: 212 | F16: =J43 | G16: =B16+D16-F16 | H16: 房屋及建築 | I16: 102 | J16: =OFFSET(A489,0,$K$1-1) | K16: =-SUMIF($C$7:$C$127,I16,$D$7:$D$127)+SUMIF($E$7:$E$127,I16,$F$7:$F$127) | L16: =VLOOKUP(A16,$A$140:$AX$249,$K$1,FALSE) | M16: =L16-G16 | O16: =L16-B16 | P16: =J16-K16 | Q16: =D16-F16
A17: 投資、長期應收款、貸墊款及準備金 | B17: =SUM(B18:B21) | G17: =SUM(G18:G21) | H17: 機械及設備 | I17: 103 | J17: =OFFSET(A490,0,$K$1-1) | K17: =-SUMIF($C$7:$C$127,I17,$D$7:$D$127)+SUMIF($E$7:$E$127,I17,$F$7:$F$127) | L17: =VLOOKUP(A17,$A$140:$AX$249,$K$1,FALSE) | M17: =L17-G17 | O17: =L17-B17 | P17: =J17-K17 | Q17: =D17-F17
A18: 採權益法之投資 | B18: =VLOOKUP(A18,$A$309:$AX$418,$K$1,FALSE) | G18: =D18+F18+B18 | H18: 交通及運輸設備 | I18: 104 | J18: =OFFSET(A491,0,$K$1-1) | K18: =-SUMIF($C$7:$C$127,I18,$D$7:$D$127)+SUMIF($E$7:$E$127,I18,$F$7:$F$127) | L18: =VLOOKUP(A18,$A$140:$AX$249,$K$1,FALSE) | M18: =L18-G18 | O18: =L18-B18 | P18: =J18-K18 | Q18: =D18-F18
A19: 非流動金融資產 | B19: =VLOOKUP(A19,$A$309:$AX$418,$K$1,FALSE) | C19: 241 | D19: =J52*-1 | E19: 221 | F19: =J45 | G19: =B19+D19-F19 | H19: 什項設備 | I19: 105 | J19: =OFFSET(A492,0,$K$1-1) | K19: =-SUMIF($C$7:$C$127,I19,$D$7:$D$127)+SUMIF($E$7:$E$127,I19,$F$7:$F$127) | L19: =VLOOKUP(A19,$A$140:$AX$249,$K$1,FALSE) | M19: =L19-G19 | O19: =L19-B19 | P19: =J19-K19 | Q19: =D19-F19
A20: 長期應收款 | B20: =VLOOKUP(A20,$A$309:$AX$418,$K$1,FALSE) | G20: =B20+D20-F20 | H20: 租賃資產 | I20: 106 | J20: =OFFSET(A493,0,$K$1-1) | K20: =-SUMIF($C$7:$C$127,I20,$D$7:$D$127)+SUMIF($E$7:$E$127,I20,$F$7:$F$127) | L20: =VLOOKUP(A20,$A$140:$AX$249,$K$1,FALSE) | M20: =L20-G20 | O20: =L20-B20 | P20: =J20-K20 | Q20: =D20-F20
A21: 準備金 | B21: =VLOOKUP(A21,$A$309:$AX$418,$K$1,FALSE) | C21: 242 | D21: =J53*-1 | E21: 222 | F21: =J46 | G21: =B21+SUM(D21:D25)-SUM(F21:F25) | H21: 租賃權益改良 | I21: 107 | J21: =OFFSET(A494,0,$K$1-1) | K21: =-SUMIF($C$7:$C$127,I21,$D$7:$D$127)+SUMIF($E$7:$E$127,I21,$F$7:$F$127) | L21: =VLOOKUP(A21,$A$140:$AX$249,$K$1,FALSE) | M21: =L21-G21 | O21: =L21-B21 | P21: =J21-K21 | Q21: =D21-F21
A22: 0 | C22: 401 | D22: =J90 | E22: 402 | F22: =-J91 | H22: 代管資產 | I22: 108 | J22: =OFFSET(A495,0,$K$1-1) | K22: =-SUMIF($C$7:$C$127,I22,$D$7:$D$127)+SUMIF($E$7:$E$127,I22,$F$7:$F$127) | M22: =L22-G22 | O22: =L22-B22 | P22: =J22-K22 | Q22: =D22-F22
A23: 0 | C23: 403 | D23: =J93 | H23: 生產性生物資產－非流動 | I23: 109 | J23: =OFFSET(A496,0,$K$1-1) | K23: =-SUMIF($C$7:$C$127,I23,$D$7:$D$127)+SUMIF($E$7:$E$127,I23,$F$7:$F$127) | M23: =L23-G23 | O23: =L23-B23 | P23: =J23-K23 | Q23: =D23-F23
A24: 0 | H24: 攤銷 | J24: =OFFSET(A497,0,$K$1-1) | K24: =SUM(K25:K26) | M24: =L24-G24 | O24: =L24-B24 | P24: =J24-K24 | Q24: =D24-F24
C25: 125 | D25: =J32*-1 | H25: 攤銷電腦軟體 | I25: 111 | J25: =OFFSET(A498,0,$K$1-1) | K25: =-SUMIF($C$7:$C$127,I25,$D$7:$D$127)+SUMIF($E$7:$E$127,I25,$F$7:$F$127) | M25: =L25-G25 | O25: =L25-B25 | P25: =J25-K25 | Q25: =D25-F25
A26: 不動產、廠房及設備 | B26: =SUM(B27:B52) | G26: =SUM(G27:G52) | H26: 其他攤銷費用 | I26: 112 | J26: =OFFSET(A499,0,$K$1-1) | K26: =-SUMIF($C$7:$C$127,I26,$D$7:$D$127)+SUMIF($E$7:$E$127,I26,$F$7:$F$127) | L26: =VLOOKUP(A26,$A$140:$AX$249,$K$1,FALSE) | M26: =L26-G26 | O26: =L26-B26 | P26: =J26-K26 | Q26: =D26-F26
A27: 土地 | B27: =VLOOKUP(A27,$A$309:$AX$418,$K$1,FALSE) | C27: 121 | G27: =B27+SUM(D27)-SUM(F27) | H27: 其他 | J27: =OFFSET(A500,0,$K$1-1) | K27: =K28+K29+K32 | L27: =VLOOKUP(A27,$A$140:$AX$249,$K$1,FALSE) | M27: =L27-G27 | O27: =L27-B27 | P27: =J27-K27 | Q27: =D27-F27
A28: 0 | H28: 應付退休及離職金 | I28: 122 | J28: =OFFSET(A501,0,$K$1-1) | K28: =-SUMIF($C$7:$C$127,I28,$D$7:$D$127)+SUMIF($E$7:$E$127,I28,$F$7:$F$127) | M28: =L28-G28 | O28: =L28-B28 | P28: =J28-K28 | Q28: =D28-F28
A29: 土地改良物 | B29: =VLOOKUP(A29,$A$309:$AX$418,$K$1,FALSE) | C29: 251 | D29: =J57*-1 | E29: 101 | F29: =J15 | G29: =B29+SUM(D29:D32)-SUM(F29:F32) | H29: 遞延收入 | J29: =OFFSET(A502,0,$K$1-1) | K29: =SUM(K30:K31) | L29: =VLOOKUP(A29,$A$140:$AX$249,$K$1,FALSE) | M29: =L29-G29 | O29: =L29-B29 | P29: =J29-K29 | Q29: =D29-F29
A30: 0 | C30: 404 | D30: =J96 | H30: 遞延收入-其他補助收入 | I30: 123 | J30: =OFFSET(A503,0,$K$1-1) | K30: =-SUMIF($C$7:$C$127,I30,$D$7:$D$127)+SUMIF($E$7:$E$127,I30,$F$7:$F$127) | M30: =L30-G30 | O30: =L30-B30 | P30: =J30-K30 | Q30: =D30-F30
A31: 0 | H31: 遞延收入-受贈收入 | I31: 124 | J31: =OFFSET(A504,0,$K$1-1) | K31: =-SUMIF($C$7:$C$127,I31,$D$7:$D$127)+SUMIF($E$7:$E$127,I31,$F$7:$F$127) | M31: =L31-G31 | O31: =L31-B31 | P31: =J31-K31 | Q31: =D31-F31
A32: 0 | H32: 其他 | I32: 125 | J32: =OFFSET(A505,0,$K$1-1) | M32: =L32-G32 | O32: =L32-B32 | P32: =J32-K32 | Q32: =D32-F32
A33: 房屋及建築 | B33: =VLOOKUP(A33,$A$309:$AX$418,$K$1,FALSE) | C33: 252 | D33: =J58*-1 | E33: 102 | F33: =J16 | G33: =B33+SUM(D33:D36)-SUM(F33:F36) | H33: 流動資產淨減（淨增） | I33: 151 | J33: =OFFSET(A506,0,$K$1-1) | K33: =-SUMIF($C$7:$C$127,I33,$D$7:$D$127)+SUMIF($E$7:$E$127,I33,$F$7:$F$127) | L33: =VLOOKUP(A33,$A$140:$AX$249,$K$1,FALSE) | M33: =L33-G33 | O33: =L33-B33 | P33: =J33-K33 | Q33: =D33-F33
A34: 0 | C34: 405 | D34: =J97 | H34: 流動負債淨增（淨減） | I34: 161 | J34: =OFFSET(A507,0,$K$1-1) | K34: =-SUMIF($C$7:$C$127,I34,$D$7:$D$127)+SUMIF($E$7:$E$127,I34,$F$7:$F$127) | M34: =L34-G34 | O34: =L34-B34 | P34: =J34-K34 | Q34: =D34-F34
A35: 0 | H35: 未計利息股利之現金流入（流出） | J35: =OFFSET(A508,0,$K$1-1) | K35: =K12+K13 | M35: =L35-G35 | O35: =L35-B35 | P35: =J35-K35 | Q35: =D35-F35
A36: 0 | H36: 收取利息 | J36: =OFFSET(A509,0,$K$1-1) | K36: =J36 | M36: =L36-G36 | O36: =L36-B36 | P36: =J36-K36 | Q36: =D36-F36
A37: 機械及設備 | B37: =VLOOKUP(A37,$A$309:$AX$418,$K$1,FALSE) | C37: 253 | D37: =J59*-1 | E37: 103 | F37: =J17 | G37: =B37+SUM(D37:D41)-SUM(F37:F41) | H37: 收取股利 | J37: =OFFSET(A510,0,$K$1-1) | K37: =J37 | L37: =VLOOKUP(A37,$A$140:$AX$249,$K$1,FALSE) | M37: =L37-G37 | O37: =L37-B37 | P37: =J37-K37 | Q37: =D37-F37
A38: 0 | C38: 407 | D38: =J101 | H38: 支付利息 | J38: =OFFSET(A511,0,$K$1-1) | K38: =J38 | M38: =L38-G38 | O38: =L38-B38 | P38: =J38-K38 | Q38: =D38-F38
A39: 0 | C39: 409 | D39: =J105 | E39: 412 | F39: =-J109 | H39: ▼業務活動之淨現金流入（流出） | J39: =OFFSET(A512,0,$K$1-1) | K39: =K36+K37+K38+K35 | M39: =L39-G39 | O39: =L39-B39 | P39: =J39-K39 | Q39: =D39-F39
A40: 0 | H40: ▼投資活動之現金流量 | J40: =OFFSET(A513,0,$K$1-1) | K40: =SUM(K41,K44,K47,K48,K49,K51,K54,K64) | M40: =L40-G40 | O40: =L40-B40 | P40: =J40-K40 | Q40: =D40-F40
...

Sheet 中興
A1: =OFFSET(A139,0,K1-1) | K1: =L1+2 | L1: 4
A2: 預計平衡表與現金流量表勾稽底稿
A3: 中華民國115年度
A4: 科目 | B4: 114.12.31 | C4: 調整項目 | G4: 115.12.31 | H4: 現金流量表勾稽項目
B5: 預計數 | D5: 借方 | F5: 貸方 | G5: 預計數
A6: 資產 | H6: ▼業務活動之現金流量 | L6: 114年12月 | M6: 差異數要再加(減) | O6: 比較增減 | Q6: 調整項目
A7: 流動資產 | B7: =SUM(B8:B16) | G7: =SUM(G8:G16) | H7: 本期賸餘（短絀） | I7: A | J7: =OFFSET(A480,0,$K$1-1) | K7: =-SUMIF($C$7:$C$127,I7,$D$7:$D$127)+SUMIF($E$7:$E$127,I7,$F$7:$F$127) | L7: =VLOOKUP(A7,$A$140:$AX$249,$K$1,FALSE) | M7: =L7-G7 | O7: =L7-B7 | P7: =J7-K7 | Q7: =D7-F7
A8: 現金 | B8: =VLOOKUP(A8,$A$309:$AX$418,$K$1,FALSE) | C8: B | D8: =IF(G8-B8>0,G8-B8,"0") | E8: B | F8: =IF(G8-B8<0,B8-G8,"0") | G8: =J87 | H8: 利息股利之調整 | J8: =OFFSET(A481,0,$K$1-1) | K8: =SUM(K9:K11) | L8: =VLOOKUP(A8,$A$140:$AX$249,$K$1,FALSE) | M8: =L8-G8 | O8: =L8-B8 | P8: =J8-K8 | Q8: =D8-F8
A9: 流動金融資產 | B9: =VLOOKUP(A9,$A$309:$AX$418,$K$1,FALSE) | C9: 231 | D9: =J50*-1 | E9: 211 | F9: =J42 | G9: =B9+D9-F9+D10-F10 | H9: 利息收入 | J9: =OFFSET(A482,0,$K$1-1) | K9: =J9 | L9: =VLOOKUP(A9,$A$140:$AX$249,$K$1,FALSE) | M9: =L9-G9 | O9: =L9-B9 | P9: =J9-K9 | Q9: =D9-F9
C10: 125 | H10: 股利收入 | J10: =OFFSET(A483,0,$K$1-1) | K10: =J10 | M10: =L10-G10 | O10: =L10-B10 | P10: =J10-K10 | Q10: =D10-F10
A11: 應收款項 | B11: =VLOOKUP(A11,$A$309:$AX$418,$K$1,FALSE) | C11: 151 | E11: 151 | G11: =B11+D11-F11 | H11: 利息費用 | J11: =OFFSET(A484,0,$K$1-1) | K11: =J11 | L11: =VLOOKUP(A11,$A$140:$AX$249,$K$1,FALSE) | M11: =L11-G11 | O11: =L11-B11 | P11: =J11-K11 | Q11: =D11-F11
A12: 0 | H12: 未計利息股利之本期賸餘（短絀） | J12: =OFFSET(A485,0,$K$1-1) | K12: =K7+K8 | M12: =L12-G12 | O12: =L12-B12 | P12: =J12-K12 | Q12: =D12-F12
A13: 存貨 | B13: =VLOOKUP(A13,$A$309:$AX$418,$K$1,FALSE) | C13: 151 | E13: 151 | G13: =B13+D13-F13 | H13: 調整項目 | J13: =OFFSET(A486,0,$K$1-1) | K13: =SUM(K14,K24,K27,K34,K33) | L13: =VLOOKUP(A13,$A$140:$AX$249,$K$1,FALSE) | M13: =L13-G13 | O13: =L13-B13 | P13: =J13-K13 | Q13: =D13-F13
A14: 生產性生物資產－流動 | B14: =VLOOKUP(A14,$A$309:$AX$418,$K$1,FALSE) | C14: 151 | E14: 151 | G14: =B14+D14-F14 | H14: 折舊、減損及折耗 | J14: =OFFSET(A487,0,$K$1-1) | K14: =SUM(K15:K23) | L14: =VLOOKUP(A14,$A$140:$AX$249,$K$1,FALSE) | M14: =L14-G14 | O14: =L14-B14 | P14: =J14-K14 | Q14: =D14-F14
A15: 預付款項 | B15: =VLOOKUP(A15,$A$309:$AX$418,$K$1,FALSE) | C15: 151 | E15: 151 | G15: =B15+D15-F15 | H15: 土地改良物 | I15: 101 | J15: =OFFSET(A488,0,$K$1-1) | K15: =-SUMIF($C$7:$C$127,I15,$D$7:$D$127)+SUMIF($E$7:$E$127,I15,$F$7:$F$127) | L15: =VLOOKUP(A15,$A$140:$AX$249,$K$1,FALSE) | M15: =L15-G15 | O15: =L15-B15 | P15: =J15-K15 | Q15: =D15-F15
A16: 短期貸墊款 | B16: =VLOOKUP(A16,$A$309:$AX$418,$K$1,FALSE) | C16: 151 | E16: 212 | F16: =J43 | G16: =B16+D16-F16 | H16: 房屋及建築 | I16: 102 | J16: =OFFSET(A489,0,$K$1-1) | K16: =-SUMIF($C$7:$C$127,I16,$D$7:$D$127)+SUMIF($E$7:$E$127,I16,$F$7:$F$127) | L16: =VLOOKUP(A16,$A$140:$AX$249,$K$1,FALSE) | M16: =L16-G16 | O16: =L16-B16 | P16: =J16-K16 | Q16: =D16-F16
A17: 投資、長期應收款、貸墊款及準備金 | B17: =SUM(B18:B21) | G17: =SUM(G18:G21) | H17: 機械及設備 | I17: 103 | J17: =OFFSET(A490,0,$K$1-1) | K17: =-SUMIF($C$7:$C$127,I17,$D$7:$D$127)+SUMIF($E$7:$E$127,I17,$F$7:$F$127) | L17: =VLOOKUP(A17,$A$140:$AX$249,$K$1,FALSE) | M17: =L17-G17 | O17: =L17-B17 | P17: =J17-K17 | Q17: =D17-F17
A18: 採權益法之投資 | B18: =VLOOKUP(A18,$A$309:$AX$418,$K$1,FALSE) | G18: =D18+F18+B18 | H18: 交通及運輸設備 | I18: 104 | J18: =OFFSET(A491,0,$K$1-1) | K18: =-SUMIF($C$7:$C$127,I18,$D$7:$D$127)+SUMIF($E$7:$E$127,I18,$F$7:$F$127) | L18: =VLOOKUP(A18,$A$140:$AX$249,$K$1,FALSE) | M18: =L18-G18 | O18: =L18-B18 | P18: =J18-K18 | Q18: =D18-F18
A19: 非流動金融資產 | B19: =VLOOKUP(A19,$A$309:$AX$418,$K$1,FALSE) | C19: 241 | D19: =J52*-1 | E19: 221 | F19: =J45 | G19: =B19+D19-F19 | H19: 什項設備 | I19: 105 | J19: =OFFSET(A492,0,$K$1-1) | K19: =-SUMIF($C$7:$C$127,I19,$D$7:$D$127)+SUMIF($E$7:$E$127,I19,$F$7:$F$127) | L19: =VLOOKUP(A19,$A$140:$AX$249,$K$1,FALSE) | M19: =L19-G19 | O19: =L19-B19 | P19: =J19-K19 | Q19: =D19-F19
A20: 長期應收款 | B20: =VLOOKUP(A20,$A$309:$AX$418,$K$1,FALSE) | G20: =B20+D20-F20 | H20: 租賃資產 | I20: 106 | J20: =OFFSET(A493,0,$K$1-1) | K20: =-SUMIF($C$7:$C$127,I20,$D$7:$D$127)+SUMIF($E$7:$E$127,I20,$F$7:$F$127) | L20: =VLOOKUP(A20,$A$140:$AX$249,$K$1,FALSE) | M20: =L20-G20 | O20: =L20-B20 | P20: =J20-K20 | Q20: =D20-F20
A21: 準備金 | B21: =VLOOKUP(A21,$A$309:$AX$418,$K$1,FALSE) | C21: 242 | D21: =J53*-1 | E21: 222 | F21: =J46 | G21: =B21+SUM(D21:D25)-SUM(F21:F25) | H21: 租賃權益改良 | I21: 107 | J21: =OFFSET(A494,0,$K$1-1) | K21: =-SUMIF($C$7:$C$127,I21,$D$7:$D$127)+SUMIF($E$7:$E$127,I21,$F$7:$F$127) | L21: =VLOOKUP(A21,$A$140:$AX$249,$K$1,FALSE) | M21: =L21-G21 | O21: =L21-B21 | P21: =J21-K21 | Q21: =D21-F21
A22: 0 | C22: 401 | D22: =J90 | E22: 402 | F22: =-J91 | H22: 代管資產 | I22: 108 | J22: =OFFSET(A495,0,$K$1-1) | K22: =-SUMIF($C$7:$C$127,I22,$D$7:$D$127)+SUMIF($E$7:$E$127,I22,$F$7:$F$127) | M22: =L22-G22 | O22: =L22-B22 | P22: =J22-K22 | Q22: =D22-F22
A23: 0 | C23: 403 | D23: =J93 | H23: 生產性生物資產－非流動 | I23: 109 | J23: =OFFSET(A496,0,$K$1-1) | K23: =-SUMIF($C$7:$C$127,I23,$D$7:$D$127)+SUMIF($E$7:$E$127,I23,$F$7:$F$127) | M23: =L23-G23 | O23: =L23-B23 | P23: =J23-K23 | Q23: =D23-F23
A24: 0 | H24: 攤銷 | J24: =OFFSET(A497,0,$K$1-1) | K24: =SUM(K25:K26) | M24: =L24-G24 | O24: =L24-B24 | P24: =J24-K24 | Q24: =D24-F24
C25: 125 | D25: =J32*-1 | H25: 攤銷電腦軟體 | I25: 111 | J25: =OFFSET(A498,0,$K$1-1) | K25: =-SUMIF($C$7:$C$127,I25,$D$7:$D$127)+SUMIF($E$7:$E$127,I25,$F$7:$F$127) | M25: =L25-G25 | O25: =L25-B25 | P25: =J25-K25 | Q25: =D25-F25
A26: 不動產、廠房及設備 | B26: =SUM(B27:B52) | G26: =SUM(G27:G52) | H26: 其他攤銷費用 | I26: 112 | J26: =OFFSET(A499,0,$K$1-1) | K26: =-SUMIF($C$7:$C$127,I26,$D$7:$D$127)+SUMIF($E$7:$E$127,I26,$F$7:$F$127) | L26: =VLOOKUP(A26,$A$140:$AX$249,$K$1,FALSE) | M26: =L26-G26 | O26: =L26-B26 | P26: =J26-K26 | Q26: =D26-F26
A27: 土地 | B27: =VLOOKUP(A27,$A$309:$AX$418,$K$1,FALSE) | C27: 121 | G27: =B27+SUM(D27)-SUM(F27) | H27: 其他 | J27: =OFFSET(A500,0,$K$1-1) | K27: =K28+K29+K32 | L27: =VLOOKUP(A27,$A$140:$AX$249,$K$1,FALSE) | M27: =L27-G27 | O27: =L27-B27 | P27: =J27-K27 | Q27: =D27-F27
A28: 0 | H28: 應付退休及離職金 | I28: 122 | J28: =OFFSET(A501,0,$K$1-1) | K28: =-SUMIF($C$7:$C$127,I28,$D$7:$D$127)+SUMIF($E$7:$E$127,I28,$F$7:$F$127) | M28: =L28-G28 | O28: =L28-B28 | P28: =J28-K28 | Q28: =D28-F28
A29: 土地改良物 | B29: =VLOOKUP(A29,$A$309:$AX$418,$K$1,FALSE) | C29: 251 | D29: =J57*-1 | E29: 101 | F29: =J15 | G29: =B29+SUM(D29:D32)-SUM(F29:F32) | H29: 遞延收入 | J29: =OFFSET(A502,0,$K$1-1) | K29: =SUM(K30:K31) | L29: =VLOOKUP(A29,$A$140:$AX$249,$K$1,FALSE) | M29: =L29-G29 | O29: =L29-B29 | P29: =J29-K29 | Q29: =D29-F29
A30: 0 | C30: 404 | D30: =J96 | H30: 遞延收入-其他補助收入 | I30: 123 | J30: =OFFSET(A503,0,$K$1-1) | K30: =-SUMIF($C$7:$C$127,I30,$D$7:$D$127)+SUMIF($E$7:$E$127,I30,$F$7:$F$127) | M30: =L30-G30 | O30: =L30-B30 | P30: =J30-K30 | Q30: =D30-F30
A31: 0 | H31: 遞延收入-受贈收入 | I31: 124 | J31: =OFFSET(A504,0,$K$1-1) | K31: =-SUMIF($C$7:$C$127,I31,$D$7:$D$127)+SUMIF($E$7:$E$127,I31,$F$7:$F$127) | M31: =L31-G31 | O31: =L31-B31 | P31: =J31-K31 | Q31: =D31-F31
A32: 0 | H32: 其他 | I32: 125 | J32: =OFFSET(A505,0,$K$1-1) | M32: =L32-G32 | O32: =L32-B32 | P32: =J32-K32 | Q32: =D32-F32
A33: 房屋及建築 | B33: =VLOOKUP(A33,$A$309:$AX$418,$K$1,FALSE) | C33: 252 | D33: =J58*-1 | E33: 102 | F33: =J16 | G33: =B33+SUM(D33:D36)-SUM(F33:F36) | H33: 流動資產淨減（淨增） | I33: 151 | J33: =OFFSET(A506,0,$K$1-1) | K33: =-SUMIF($C$7:$C$127,I33,$D$7:$D$127)+SUMIF($E$7:$E$127,I33,$F$7:$F$127) | L33: =VLOOKUP(A33,$A$140:$AX$249,$K$1,FALSE) | M33: =L33-G33 | O33: =L33-B33 | P33: =J33-K33 | Q33: =D33-F33
A34: 0 | C34: 405 | D34: =J97 | H34: 流動負債淨增（淨減） | I34: 161 | J34: =OFFSET(A507,0,$K$1-1) | K34: =-SUMIF($C$7:$C$127,I34,$D$7:$D$127)+SUMIF($E$7:$E$127,I34,$F$7:$F$127) | M34: =L34-G34 | O34: =L34-B34 | P34: =J34-K34 | Q34: =D34-F34
A35: 0 | H35: 未計利息股利之現金流入（流出） | J35: =OFFSET(A508,0,$K$1-1) | K35: =K12+K13 | M35: =L35-G35 | O35: =L35-B35 | P35: =J35-K35 | Q35: =D35-F35
A36: 0 | H36: 收取利息 | J36: =OFFSET(A509,0,$K$1-1) | K36: =J36 | M36: =L36-G36 | O36: =L36-B36 | P36: =J36-K36 | Q36: =D36-F36
A37: 機械及設備 | B37: =VLOOKUP(A37,$A$309:$AX$418,$K$1,FALSE) | C37: 253 | D37: =J59*-1 | E37: 103 | F37: =J17 | G37: =B37+SUM(D37:D41)-SUM(F37:F41) | H37: 收取股利 | J37: =OFFSET(A510,0,$K$1-1) | K37: =J37 | L37: =VLOOKUP(A37,$A$140:$AX$249,$K$1,FALSE) | M37: =L37-G37 | O37: =L37-B37 | P37: =J37-K37 | Q37: =D37-F37
A38: 0 | C38: 407 | D38: =J101 | H38: 支付利息 | J38: =OFFSET(A511,0,$K$1-1) | K38: =J38 | M38: =L38-G38 | O38: =L38-B38 | P38: =J38-K38 | Q38: =D38-F38
A39: 0 | C39: 409 | D39: =J105 | E39: 412 | F39: =-J109 | H39: ▼業務活動之淨現金流入（流出） | J39: =OFFSET(A512,0,$K$1-1) | K39: =K36+K37+K38+K35 | M39: =L39-G39 | O39: =L39-B39 | P39: =J39-K39 | Q39: =D39-F39
A40: 0 | H40: ▼投資活動之現金流量 | J40: =OFFSET(A513,0,$K$1-1) | K40: =SUM(K41,K44,K47,K48,K49,K51,K54,K64) | M40: =L40-G40 | O40: =L40-B40 | P40: =J40-K40 | Q40: =D40-F40
...

Sheet 成大
A1: =OFFSET(A139,0,K1-1) | K1: =L1+2 | L1: 5
A2: 預計平衡表與現金流量表勾稽底稿
A3: 中華民國115年度
A4: 科目 | B4: 114.12.31 | C4: 調整項目 | G4: 115.12.31 | H4: 現金流量表勾稽項目
B5: 預計數 | D5: 借方 | F5: 貸方 | G5: 預計數
A6: 資產 | H6: ▼業務活動之現金流量 | L6: 114年12月 | M6: 差異數要再加(減) | O6: 比較增減 | Q6: 調整項目
A7: 流動資產 | B7: =SUM(B8:B16) | G7: =SUM(G8:G16) | H7: 本期賸餘（短絀） | I7: A | J7: =OFFSET(A480,0,$K$1-1) | K7: =-SUMIF($C$7:$C$127,I7,$D$7:$D$127)+SUMIF($E$7:$E$127,I7,$F$7:$F$127) | L7: =VLOOKUP(A7,$A$140:$AX$249,$K$1,FALSE) | M7: =L7-G7 | O7: =L7-B7 | P7: =J7-K7 | Q7: =D7-F7
A8: 現金 | B8: =VLOOKUP(A8,$A$309:$AX$418,$K$1,FALSE) | C8: B | D8: =IF(G8-B8>0,G8-B8,"0") | E8: B | F8: =IF(G8-B8<0,B8-G8,"0") | G8: =J87 | H8: 利息股利之調整 | J8: =OFFSET(A481,0,$K$1-1) | K8: =SUM(K9:K11) | L8: =VLOOKUP(A8,$A$140:$AX$249,$K$1,FALSE) | M8: =L8-G8 | O8: =L8-B8 | P8: =J8-K8 | Q8: =D8-F8
A9: 流動金融資產 | B9: =VLOOKUP(A9,$A$309:$AX$418,$K$1,FALSE) | C9: 231 | D9: =J50*-1 | E9: 211 | F9: =J42 | G9: =B9+D9-F9+D10-F10 | H9: 利息收入 | J9: =OFFSET(A482,0,$K$1-1) | K9: =J9 | L9: =VLOOKUP(A9,$A$140:$AX$249,$K$1,FALSE) | M9: =L9-G9 | O9: =L9-B9 | P9: =J9-K9 | Q9: =D9-F9
C10: 125 | H10: 股利收入 | J10: =OFFSET(A483,0,$K$1-1) | K10: =J10 | M10: =L10-G10 | O10: =L10-B10 | P10: =J10-K10 | Q10: =D10-F10
A11: 應收款項 | B11: =VLOOKUP(A11,$A$309:$AX$418,$K$1,FALSE) | C11: 151 | E11: 151 | G11: =B11+D11-F11 | H11: 利息費用 | J11: =OFFSET(A484,0,$K$1-1) | K11: =J11 | L11: =VLOOKUP(A11,$A$140:$AX$249,$K$1,FALSE) | M11: =L11-G11 | O11: =L11-B11 | P11: =J11-K11 | Q11: =D11-F11
A12: 0 | H12: 未計利息股利之本期賸餘（短絀） | J12: =OFFSET(A485,0,$K$1-1) | K12: =K7+K8 | M12: =L12-G12 | O12: =L12-B12 | P12: =J12-K12 | Q12: =D12-F12
A13: 存貨 | B13: =VLOOKUP(A13,$A$309:$AX$418,$K$1,FALSE) | C13: 151 | E13: 151 | G13: =B13+D13-F13 | H13: 調整項目 | J13: =OFFSET(A486,0,$K$1-1) | K13: =SUM(K14,K24,K27,K34,K33) | L13: =VLOOKUP(A13,$A$140:$AX$249,$K$1,FALSE) | M13: =L13-G13 | O13: =L13-B13 | P13: =J13-K13 | Q13: =D13-F13
A14: 生產性生物資產－流動 | B14: =VLOOKUP(A14,$A$309:$AX$418,$K$1,FALSE) | C14: 151 | E14: 151 | G14: =B14+D14-F14 | H14: 折舊、減損及折耗 | J14: =OFFSET(A487,0,$K$1-1) | K14: =SUM(K15:K23) | L14: =VLOOKUP(A14,$A$140:$AX$249,$K$1,FALSE) | M14: =L14-G14 | O14: =L14-B14 | P14: =J14-K14 | Q14: =D14-F14
A15: 預付款項 | B15: =VLOOKUP(A15,$A$309:$AX$418,$K$1,FALSE) | C15: 151 | E15: 151 | G15: =B15+D15-F15 | H15: 土地改良物 | I15: 101 | J15: =OFFSET(A488,0,$K$1-1) | K15: =-SUMIF($C$7:$C$127,I15,$D$7:$D$127)+SUMIF($E$7:$E$127,I15,$F$7:$F$127) | L15: =VLOOKUP(A15,$A$140:$AX$249,$K$1,FALSE) | M15: =L15-G15 | O15: =L15-B15 | P15: =J15-K15 | Q15: =D15-F15
A16: 短期貸墊款 | B16: =VLOOKUP(A16,$A$309:$AX$418,$K$1,FALSE) | C16: 151 | E16: 212 | F16: =J43 | G16: =B16+D16-F16 | H16: 房屋及建築 | I16: 102 | J16: =OFFSET(A489,0,$K$1-1) | K16: =-SUMIF($C$7:$C$127,I16,$D$7:$D$127)+SUMIF($E$7:$E$127,I16,$F$7:$F$127) | L16: =VLOOKUP(A16,$A$140:$AX$249,$K$1,FALSE) | M16: =L16-G16 | O16: =L16-B16 | P16: =J16-K16 | Q16: =D16-F16
A17: 投資、長期應收款、貸墊款及準備金 | B17: =SUM(B18:B21) | G17: =SUM(G18:G21) | H17: 機械及設備 | I17: 103 | J17: =OFFSET(A490,0,$K$1-1) | K17: =-SUMIF($C$7:$C$127,I17,$D$7:$D$127)+SUMIF($E$7:$E$127,I17,$F$7:$F$127) | L17: =VLOOKUP(A17,$A$140:$AX$249,$K$1,FALSE) | M17: =L17-G17 | O17: =L17-B17 | P17: =J17-K17 | Q17: =D17-F17
A18: 採權益法之投資 | B18: =VLOOKUP(A18,$A$309:$AX$418,$K$1,FALSE) | G18: =D18+F18+B18 | H18: 交通及運輸設備 | I18: 104 | J18: =OFFSET(A491,0,$K$1-1) | K18: =-SUMIF($C$7:$C$127,I18,$D$7:$D$127)+SUMIF($E$7:$E$127,I18,$F$7:$F$127) | L18: =VLOOKUP(A18,$A$140:$AX$249,$K$1,FALSE) | M18: =L18-G18 | O18: =L18-B18 | P18: =J18-K18 | Q18: =D18-F18
A19: 非流動金融資產 | B19: =VLOOKUP(A19,$A$309:$AX$418,$K$1,FALSE) | C19: 241 | D19: =J52*-1 | E19: 221 | F19: =J45 | G19: =B19+D19-F19 | H19: 什項設備 | I19: 105 | J19: =OFFSET(A492,0,$K$1-1) | K19: =-SUMIF($C$7:$C$127,I19,$D$7:$D$127)+SUMIF($E$7:$E$127,I19,$F$7:$F$127) | L19: =VLOOKUP(A19,$A$140:$AX$249,$K$1,FALSE) | M19: =L19-G19 | O19: =L19-B19 | P19: =J19-K19 | Q19: =D19-F19
A20: 長期應收款 | B20: =VLOOKUP(A20,$A$309:$AX$418,$K$1,FALSE) | G20: =B20+D20-F20 | H20: 租賃資產 | I20: 106 | J20: =OFFSET(A493,0,$K$1-1) | K20: =-SUMIF($C$7:$C$127,I20,$D$7:$D$127)+SUMIF($E$7:$E$127,I20,$F$7:$F$127) | L20: =VLOOKUP(A20,$A$140:$AX$249,$K$1,FALSE) | M20: =L20-G20 | O20: =L20-B20 | P20: =J20-K20 | Q20: =D20-F20
A21: 準備金 | B21: =VLOOKUP(A21,$A$309:$AX$418,$K$1,FALSE) | C21: 242 | D21: =J53*-1 | E21: 222 | F21: =J46 | G21: =B21+SUM(D21:D25)-SUM(F21:F25) | H21: 租賃權益改良 | I21: 107 | J21: =OFFSET(A494,0,$K$1-1) | K21: =-SUMIF($C$7:$C$127,I21,$D$7:$D$127)+SUMIF($E$7:$E$127,I21,$F$7:$F$127) | L21: =VLOOKUP(A21,$A$140:$AX$249,$K$1,FALSE) | M21: =L21-G21 | O21: =L21-B21 | P21: =J21-K21 | Q21: =D21-F21
A22: 0 | C22: 401 | D22: =J90 | E22: 402 | F22: =-J91 | H22: 代管資產 | I22: 108 | J22: =OFFSET(A495,0,$K$1-1) | K22: =-SUMIF($C$7:$C$127,I22,$D$7:$D$127)+SUMIF($E$7:$E$127,I22,$F$7:$F$127) | M22: =L22-G22 | O22: =L22-B22 | P22: =J22-K22 | Q22: =D22-F22
A23: 0 | C23: 403 | D23: =J93 | H23: 生產性生物資產－非流動 | I23: 109 | J23: =OFFSET(A496,0,$K$1-1) | K23: =-SUMIF($C$7:$C$127,I23,$D$7:$D$127)+SUMIF($E$7:$E$127,I23,$F$7:$F$127) | M23: =L23-G23 | O23: =L23-B23 | P23: =J23-K23 | Q23: =D23-F23
A24: 0 | H24: 攤銷 | J24: =OFFSET(A497,0,$K$1-1) | K24: =SUM(K25:K26) | M24: =L24-G24 | O24: =L24-B24 | P24: =J24-K24 | Q24: =D24-F24
C25: 125 | D25: =J32*-1 | H25: 攤銷電腦軟體 | I25: 111 | J25: =OFFSET(A498,0,$K$1-1) | K25: =-SUMIF($C$7:$C$127,I25,$D$7:$D$127)+SUMIF($E$7:$E$127,I25,$F$7:$F$127) | M25: =L25-G25 | O25: =L25-B25 | P25: =J25-K25 | Q25: =D25-F25
A26: 不動產、廠房及設備 | B26: =SUM(B27:B52) | G26: =SUM(G27:G52) | H26: 其他攤銷費用 | I26: 112 | J26: =OFFSET(A499,0,$K$1-1) | K26: =-SUMIF($C$7:$C$127,I26,$D$7:$D$127)+SUMIF($E$7:$E$127,I26,$F$7:$F$127) | L26: =VLOOKUP(A26,$A$140:$AX$249,$K$1,FALSE) | M26: =L26-G26 | O26: =L26-B26 | P26: =J26-K26 | Q26: =D26-F26
A27: 土地 | B27: =VLOOKUP(A27,$A$309:$AX$418,$K$1,FALSE) | C27: 121 | G27: =B27+SUM(D27)-SUM(F27) | H27: 其他 | J27: =OFFSET(A500,0,$K$1-1) | K27: =K28+K29+K32 | L27: =VLOOKUP(A27,$A$140:$AX$249,$K$1,FALSE) | M27: =L27-G27 | O27: =L27-B27 | P27: =J27-K27 | Q27: =D27-F27
A28: 0 | H28: 應付退休及離職金 | I28: 122 | J28: =OFFSET(A501,0,$K$1-1) | K28: =-SUMIF($C$7:$C$127,I28,$D$7:$D$127)+SUMIF($E$7:$E$127,I28,$F$7:$F$127) | M28: =L28-G28 | O28: =L28-B28 | P28: =J28-K28 | Q28: =D28-F28
A29: 土地改良物 | B29: =VLOOKUP(A29,$A$309:$AX$418,$K$1,FALSE) | C29: 251 | D29: =J57*-1 | E29: 101 | F29: =J15 | G29: =B29+SUM(D29:D32)-SUM(F29:F32) | H29: 遞延收入 | J29: =OFFSET(A502,0,$K$1-1) | K29: =SUM(K30:K31) | L29: =VLOOKUP(A29,$A$140:$AX$249,$K$1,FALSE) | M29: =L29-G29 | O29: =L29-B29 | P29: =J29-K29 | Q29: =D29-F29
A30: 0 | C30: 404 | D30: =J96 | H30: 遞延收入-其他補助收入 | I30: 123 | J30: =OFFSET(A503,0,$K$1-1) | K30: =-SUMIF($C$7:$C$127,I30,$D$7:$D$127)+SUMIF($E$7:$E$127,I30,$F$7:$F$127) | M30: =L30-G30 | O30: =L30-B30 | P30: =J30-K30 | Q30: =D30-F30
A31: 0 | H31: 遞延收入-受贈收入 | I31: 124 | J31: =OFFSET(A504,0,$K$1-1) | K31: =-SUMIF($C$7:$C$127,I31,$D$7:$D$127)+SUMIF($E$7:$E$127,I31,$F$7:$F$127) | M31: =L31-G31 | O31: =L31-B31 | P31: =J31-K31 | Q31: =D31-F31
A32: 0 | H32: 其他 | I32: 125 | J32: =OFFSET(A505,0,$K$1-1) | M32: =L32-G32 | O32: =L32-B32 | P32: =J32-K32 | Q32: =D32-F32
A33: 房屋及建築 | B33: =VLOOKUP(A33,$A$309:$AX$418,$K$1,FALSE) | C33: 252 | D33: =J58*-1 | E33: 102 | F33: =J16 | G33: =B33+SUM(D33:D36)-SUM(F33:F36) | H33: 流動資產淨減（淨增） | I33: 151 | J33: =OFFSET(A506,0,$K$1-1) | K33: =-SUMIF($C$7:$C$127,I33,$D$7:$D$127)+SUMIF($E$7:$E$127,I33,$F$7:$F$127) | L33: =VLOOKUP(A33,$A$140:$AX$249,$K$1,FALSE) | M33: =L33-G33 | O33: =L33-B33 | P33: =J33-K33 | Q33: =D33-F33
A34: 0 | C34: 405 | D34: =J97 | H34: 流動負債淨增（淨減） | I34: 161 | J34: =OFFSET(A507,0,$K$1-1) | K34: =-SUMIF($C$7:$C$127,I34,$D$7:$D$127)+SUMIF($E$7:$E$127,I34,$F$7:$F$127) | M34: =L34-G34 | O34: =L34-B34 | P34: =J34-K34 | Q34: =D34-F34
A35: 0 | H35: 未計利息股利之現金流入（流出） | J35: =OFFSET(A508,0,$K$1-1) | K35: =K12+K13 | M35: =L35-G35 | O35: =L35-B35 | P35: =J35-K35 | Q35: =D35-F35
A36: 0 | H36: 收取利息 | J36: =OFFSET(A509,0,$K$1-1) | K36: =J36 | M36: =L36-G36 | O36: =L36-B36 | P36: =J36-K36 | Q36: =D36-F36
A37: 機械及設備 | B37: =VLOOKUP(A37,$A$309:$AX$418,$K$1,FALSE) | C37: 253 | D37: =J59*-1 | E37: 103 | F37: =J17 | G37: =B37+SUM(D37:D41)-SUM(F37:F41) | H37: 收取股利 | J37: =OFFSET(A510,0,$K$1-1) | K37: =J37 | L37: =VLOOKUP(A37,$A$140:$AX$249,$K$1,FALSE) | M37: =L37-G37 | O37: =L37-B37 | P37: =J37-K37 | Q37: =D37-F37
A38: 0 | C38: 407 | D38: =J101 | H38: 支付利息 | J38: =OFFSET(A511,0,$K$1-1) | K38: =J38 | M38: =L38-G38 | O38: =L38-B38 | P38: =J38-K38 | Q38: =D38-F38
A39: 0 | C39: 409 | D39: =J105 | E39: 412 | F39: =-J109 | H39: ▼業務活動之淨現金流入（流出） | J39: =OFFSET(A512,0,$K$1-1) | K39: =K36+K37+K38+K35 | M39: =L39-G39 | O39: =L39-B39 | P39: =J39-K39 | Q39: =D39-F39
A40: 0 | H40: ▼投資活動之現金流量 | J40: =OFFSET(A513,0,$K$1-1) | K40: =SUM(K41,K44,K47,K48,K49,K51,K54,K64) | M40: =L40-G40 | O40: =L40-B40 | P40: =J40-K40 | Q40: =D40-F40
...

Sheet 中央
A1: =OFFSET(A139,0,K1-1) | K1: =L1+2 | L1: 6
A2: 預計平衡表與現金流量表勾稽底稿
A3: 中華民國115年度
A4: 科目 | B4: 114.12.31 | C4: 調整項目 | G4: 115.12.31 | H4: 現金流量表勾稽項目
B5: 預計數 | D5: 借方 | F5: 貸方 | G5: 預計數
A6: 資產 | H6: ▼業務活動之現金流量 | L6: 114年12月 | M6: 差異數要再加(減) | O6: 比較增減 | Q6: 調整項目
A7: 流動資產 | B7: =SUM(B8:B16) | G7: =SUM(G8:G16) | H7: 本期賸餘（短絀） | I7: A | J7: =OFFSET(A480,0,$K$1-1) | K7: =-SUMIF($C$7:$C$127,I7,$D$7:$D$127)+SUMIF($E$7:$E$127,I7,$F$7:$F$127) | L7: =VLOOKUP(A7,$A$140:$AX$249,$K$1,FALSE) | M7: =L7-G7 | O7: =L7-B7 | P7: =J7-K7 | Q7: =D7-F7
A8: 現金 | B8: =VLOOKUP(A8,$A$309:$AX$418,$K$1,FALSE) | C8: B | D8: =IF(G8-B8>0,G8-B8,"0") | E8: B | F8: =IF(G8-B8<0,B8-G8,"0") | G8: =J87 | H8: 利息股利之調整 | J8: =OFFSET(A481,0,$K$1-1) | K8: =SUM(K9:K11) | L8: =VLOOKUP(A8,$A$140:$AX$249,$K$1,FALSE) | M8: =L8-G8 | O8: =L8-B8 | P8: =J8-K8 | Q8: =D8-F8
A9: 流動金融資產 | B9: =VLOOKUP(A9,$A$309:$AX$418,$K$1,FALSE) | C9: 231 | D9: =J50*-1 | E9: 211 | F9: =J42 | G9: =B9+D9-F9+D10-F10 | H9: 利息收入 | J9: =OFFSET(A482,0,$K$1-1) | K9: =J9 | L9: =VLOOKUP(A9,$A$140:$AX$249,$K$1,FALSE) | M9: =L9-G9 | O9: =L9-B9 | P9: =J9-K9 | Q9: =D9-F9
C10: 125 | H10: 股利收入 | J10: =OFFSET(A483,0,$K$1-1) | K10: =J10 | M10: =L10-G10 | O10: =L10-B10 | P10: =J10-K10 | Q10: =D10-F10
A11: 應收款項 | B11: =VLOOKUP(A11,$A$309:$AX$418,$K$1,FALSE) | C11: 151 | E11: 151 | G11: =B11+D11-F11 | H11: 利息費用 | J11: =OFFSET(A484,0,$K$1-1) | K11: =J11 | L11: =VLOOKUP(A11,$A$140:$AX$249,$K$1,FALSE) | M11: =L11-G11 | O11: =L11-B11 | P11: =J11-K11 | Q11: =D11-F11
A12: 0 | H12: 未計利息股利之本期賸餘（短絀） | J12: =OFFSET(A485,0,$K$1-1) | K12: =K7+K8 | M12: =L12-G12 | O12: =L12-B12 | P12: =J12-K12 | Q12: =D12-F12
A13: 存貨 | B13: =VLOOKUP(A13,$A$309:$AX$418,$K$1,FALSE) | C13: 151 | E13: 151 | G13: =B13+D13-F13 | H13: 調整項目 | J13: =OFFSET(A486,0,$K$1-1) | K13: =SUM(K14,K24,K27,K34,K33) | L13: =VLOOKUP(A13,$A$140:$AX$249,$K$1,FALSE) | M13: =L13-G13 | O13: =L13-B13 | P13: =J13-K13 | Q13: =D13-F13
A14: 生產性生物資產－流動 | B14: =VLOOKUP(A14,$A$309:$AX$418,$K$1,FALSE) | C14: 151 | E14: 151 | G14: =B14+D14-F14 | H14: 折舊、減損及折耗 | J14: =OFFSET(A487,0,$K$1-1) | K14: =SUM(K15:K23) | L14: =VLOOKUP(A14,$A$140:$AX$249,$K$1,FALSE) | M14: =L14-G14 | O14: =L14-B14 | P14: =J14-K14 | Q14: =D14-F14
A15: 預付款項 | B15: =VLOOKUP(A15,$A$309:$AX$418,$K$1,FALSE) | C15: 151 | E15: 151 | G15: =B15+D15-F15 | H15: 土地改良物 | I15: 101 | J15: =OFFSET(A488,0,$K$1-1) | K15: =-SUMIF($C$7:$C$127,I15,$D$7:$D$127)+SUMIF($E$7:$E$127,I15,$F$7:$F$127) | L15: =VLOOKUP(A15,$A$140:$AX$249,$K$1,FALSE) | M15: =L15-G15 | O15: =L15-B15 | P15: =J15-K15 | Q15: =D15-F15
A16: 短期貸墊款 | B16: =VLOOKUP(A16,$A$309:$AX$418,$K$1,FALSE) | C16: 151 | E16: 212 | F16: =J43 | G16: =B16+D16-F16 | H16: 房屋及建築 | I16: 102 | J16: =OFFSET(A489,0,$K$1-1) | K16: =-SUMIF($C$7:$C$127,I16,$D$7:$D$127)+SUMIF($E$7:$E$127,I16,$F$7:$F$127) | L16: =VLOOKUP(A16,$A$140:$AX$249,$K$1,FALSE) | M16: =L16-G16 | O16: =L16-B16 | P16: =J16-K16 | Q16: =D16-F16
A17: 投資、長期應收款、貸墊款及準備金 | B17: =SUM(B18:B21) | G17: =SUM(G18:G21) | H17: 機械及設備 | I17: 103 | J17: =OFFSET(A490,0,$K$1-1) | K17: =-SUMIF($C$7:$C$127,I17,$D$7:$D$127)+SUMIF($E$7:$E$127,I17,$F$7:$F$127) | L17: =VLOOKUP(A17,$A$140:$AX$249,$K$1,FALSE) | M17: =L17-G17 | O17: =L17-B17 | P17: =J17-K17 | Q17: =D17-F17
A18: 採權益法之投資 | B18: =VLOOKUP(A18,$A$309:$AX$418,$K$1,FALSE) | G18: =D18+F18+B18 | H18: 交通及運輸設備 | I18: 104 | J18: =OFFSET(A491,0,$K$1-1) | K18: =-SUMIF($C$7:$C$127,I18,$D$7:$D$127)+SUMIF($E$7:$E$127,I18,$F$7:$F$127) | L18: =VLOOKUP(A18,$A$140:$AX$249,$K$1,FALSE) | M18: =L18-G18 | O18: =L18-B18 | P18: =J18-K18 | Q18: =D18-F18
A19: 非流動金融資產 | B19: =VLOOKUP(A19,$A$309:$AX$418,$K$1,FALSE) | C19: 241 | D19: =J52*-1 | E19: 221 | F19: =J45 | G19: =B19+D19-F19 | H19: 什項設備 | I19: 105 | J19: =OFFSET(A492,0,$K$1-1) | K19: =-SUMIF($C$7:$C$127,I19,$D$7:$D$127)+SUMIF($E$7:$E$127,I19,$F$7:$F$127) | L19: =VLOOKUP(A19,$A$140:$AX$249,$K$1,FALSE) | M19: =L19-G19 | O19: =L19-B19 | P19: =J19-K19 | Q19: =D19-F19
A20: 長期應收款 | B20: =VLOOKUP(A20,$A$309:$AX$418,$K$1,FALSE) | G20: =B20+D20-F20 | H20: 租賃資產 | I20: 106 | J20: =OFFSET(A493,0,$K$1-1) | K20: =-SUMIF($C$7:$C$127,I20,$D$7:$D$127)+SUMIF($E$7:$E$127,I20,$F$7:$F$127) | L20: =VLOOKUP(A20,$A$140:$AX$249,$K$1,FALSE) | M20: =L20-G20 | O20: =L20-B20 | P20: =J20-K20 | Q20: =D20-F20
A21: 準備金 | B21: =VLOOKUP(A21,$A$309:$AX$418,$K$1,FALSE) | C21: 242 | D21: =J53*-1 | E21: 222 | F21: =J46 | G21: =B21+SUM(D21:D25)-SUM(F21:F25) | H21: 租賃權益改良 | I21: 107 | J21: =OFFSET(A494,0,$K$1-1) | K21: =-SUMIF($C$7:$C$127,I21,$D$7:$D$127)+SUMIF($E$7:$E$127,I21,$F$7:$F$127) | L21: =VLOOKUP(A21,$A$140:$AX$249,$K$1,FALSE) | M21: =L21-G21 | O21: =L21-B21 | P21: =J21-K21 | Q21: =D21-F21
A22: 0 | C22: 401 | D22: =J90 | E22: 402 | F22: =-J91 | H22: 代管資產 | I22: 108 | J22: =OFFSET(A495,0,$K$1-1) | K22: =-SUMIF($C$7:$C$127,I22,$D$7:$D$127)+SUMIF($E$7:$E$127,I22,$F$7:$F$127) | M22: =L22-G22 | O22: =L22-B22 | P22: =J22-K22 | Q22: =D22-F22
A23: 0 | C23: 403 | D23: =J93 | H23: 生產性生物資產－非流動 | I23: 109 | J23: =OFFSET(A496,0,$K$1-1) | K23: =-SUMIF($C$7:$C$127,I23,$D$7:$D$127)+SUMIF($E$7:$E$127,I23,$F$7:$F$127) | M23: =L23-G23 | O23: =L23-B23 | P23: =J23-K23 | Q23: =D23-F23
A24: 0 | H24: 攤銷 | J24: =OFFSET(A497,0,$K$1-1) | K24: =SUM(K25:K26) | M24: =L24-G24 | O24: =L24-B24 | P24: =J24-K24 | Q24: =D24-F24
C25: 125 | D25: =J32*-1 | H25: 攤銷電腦軟體 | I25: 111 | J25: =OFFSET(A498,0,$K$1-1) | K25: =-SUMIF($C$7:$C$127,I25,$D$7:$D$127)+SUMIF($E$7:$E$127,I25,$F$7:$F$127) | M25: =L25-G25 | O25: =L25-B25 | P25: =J25-K25 | Q25: =D25-F25
